Workbook

Sheet Start Here
A1: PurrStone v10.2 — Coder02 MP/UCR Phase 1
A4: Complete this workbook independently. The same nine blind unique generated-draft/source bundles are issued to both coders. Do not discuss, seek the identity key, or use AI/automated assistance.
A6: Package build ID | B6: purrstone-v10.2-matched-draft-phase1-r1-20260810
A7: Material-set SHA-256 | B7: 67afa8c732e79b430031f6e40678989fd5efe1fd65c0fb26d6527be54b050901
A8: Assigned coder ID | B8: Coder02
A9: Full name | B9: Coder02
A10: Professional / academic background | B10: Mechanical design engineer with an academic background in mechanical engineering and experience in product development and design review.
A11: Qualitative-research / coding experience | B11: No formal qualitative-research training; some experience reviewing user feedback and written evidence in engineering projects.
A12: Coding protocol read in full? | B12: Yes
A13: Worked independently and did not discuss judgments? | B13: Yes
A14: Did not seek the condition/item identity key? | B14: Yes
A15: No AI or automated assistance used for judgments/segmentation? | B15: Yes
A16: Started at (ISO 8601, e.g. 2026-08-10T14:30:00+08:00) | B16: 46244.607
A17: Completed at (ISO 8601 with timezone) | B17: 46244.655
A18: Typed name / signature | B18: Coder02
A19: Declaration QA | B19: =IF(AND(LEN(TRIM(B9))>=2,LEN(TRIM(B10))>=5,LEN(TRIM(B11))>=5,B12="Yes",B13="Yes",B14="Yes",B15="Yes",OR(AND(ISNUMBER(B16),B16>=DATE(2020,1,1)),IFERROR(AND(LEN(B16)>=20,ISNUMBER(SEARCH("T",B16)),OR(RIGHT(B16,1)="Z",MID(B16,LEN(B16)-5,1)="+",MID(B16,LEN(B16)-5,1)="-")),FALSE)),OR(AND(ISNUMBER(B17),B17>=DATE(2020,1,1)),IFERROR(AND(LEN(B17)>=20,ISNUMBER(SEARCH("T",B17)),OR(RIGHT(B17,1)="Z",MID(B17,LEN(B17)-5,1)="+",MID(B17,LEN(B17)-5,1)="-")),FALSE)),LEN(TRIM(B18))>=2),"PASS","INCOMPLETE") -> PASS
A22: 1 — Scope This is a supplementary post-formal matched-draft fidelity analysis. The source universe is the 10 completed formal matched pairs: 45 nominal draft items per condition. Exact duplicate draft–source bundles were removed before human coding, leaving 9 unique blind bundles.
A24: 2 — Meaning Preservation (MP) Compare only the generated draft with the displayed participant source. preserved = all material meaning is supported and no important source meaning is contradicted; not_preserved = at least one substantive meaning is added, omitted, or contradicted; uncertain = the supplied material is genuinely insufficient for a confident binary judgment.
A26: 3 — MP error category Use none only with preserved. For not_preserved choose added meaning, omitted meaning, contradicted meaning, source ambiguity, or other. For uncertain choose source ambiguity or other. Give a concise source-based rationale and confidence 1–3.
A28: 4 — UCR Phase 1 segmentation Split each generated draft into the smallest independently supportable factual or experiential propositions. Enter at least one proposition per blind item, in order, with no gaps. Do not treat the interface phrase “Typed response extract:” as a proposition. Do not label propositions supported/unsupported in Phase 1.
A30: 5 — Submission When QA Summary shows PASS, return only this completed .xlsx with the filename unchanged. Do not perform consensus or unblinding. The administrator will reconcile the two independent proposition inventories before issuing Phase 2.

Sheet Materials
A1: Blind materials — generated drafts and participant sources
A4: Use only the text shown here. Topic labels are neutral navigation aids. Condition, scenario, run and pair identities are intentionally withheld.
A5: Blind item ID | B5: Topic | C5: Generated draft | D5: Participant source
A6: MD-001 | B6: Experience | C6: Typed response extract: “It happened on a train.” “The train was packed and it stopped suddenly with a loud screeching noise. I could not move away from the crowd, and I felt trapped and overwhelmed.” | D6: SRC-01: It happened on a train. SRC-02: The train was packed and it stopped suddenly with a loud screeching noise. I could not move away from the crowd, and I felt trapped and overwhelmed.
A7: MD-002 | B7: Experience | C7: Typed response extract: “It happened on a train.” “I do not remember anything else about it.” | D7: SRC-01: It happened on a train. SRC-02: I do not remember anything else about it.
A8: MD-003 | B8: Experience | C8: Typed response extract: “A recent example was a crowded train that stopped between stations while alarms sounded. The noise and lack of space made me feel trapped and overwhelmed.” | D8: SRC-01: A recent example was a crowded train that stopped between stations while alarms sounded. The noise and lack of space made me feel trapped and overwhelmed.
A9: MD-004 | B9: Support concept reaction | C9: Typed response extract: “The squeeze interaction seems useful because it would give my hands a focus, and gentle haptics might help me pace my breathing. I would avoid scent because it can be another trigger, and I would want every feature to be optional.” | D9: SRC-01: The squeeze interaction seems useful because it would give my hands a focus, and gentle haptics might help me pace my breathing. I would avoid scent because it can be another trigger, and I would want every feature to be optional.
A10: MD-005 | B10: Coping & support | C10: Typed response extract: “I covered my ears, focused on slow breathing, and left at the next stop. A quieter carriage or a warning before the alarm would have helped. The repeated announcements did not help because they added more noise.” | D10: SRC-01: I covered my ears, focused on slow breathing, and left at the next stop. A quieter carriage or a warning before the alarm would have helped. The repeated announcements did not help because they added more noise.
A11: MD-006 | B11: Experience | C11: Typed response extract: “On a crowded train, the carriage stopped between stations while alarms sounded. The noise and crowding made me feel trapped and overwhelmed.” | D11: SRC-01: On a crowded train, the carriage stopped between stations while alarms sounded. The noise and crowding made me feel trapped and overwhelmed.
A12: MD-007 | B12: Triggers & signs | C12: Typed response extract: “The sharp braking noise, flashing carriage lights, and crowding were the strongest triggers. My shoulders tightened, my heart raced, and I felt panicked.” | D12: SRC-01: The sharp braking noise, flashing carriage lights, and crowding were the strongest triggers. My shoulders tightened, my heart raced, and I felt panicked.
A13: MD-008 | B13: Experience | C13: Typed response extract: “Last month on a crowded train, the carriage stopped between stations while alarms and announcements were sounding. People were pressed close to me, and the combined noise and crowding made me feel trapped and overwhelmed.” | D13: SRC-01: Last month on a crowded train, the carriage stopped between stations while alarms and announcements were sounding. People were pressed close to me, and the combined noise and crowding made me feel trapped and overwhelmed.
A14: MD-009 | B14: Public-use acceptability | C14: Typed response extract: “I might use it while commuting if it looked discreet and made no sound. I would be embarrassed by obvious lights, and scent would be a concern for people nearby in a shared space.” | D14: SRC-01: I might use it while commuting if it looked discreet and made no sound. I would be embarrassed by obvious lights, and scent would be a concern for people nearby in a shared space.

Sheet MP Coding
A1: Meaning Preservation coding and UCR item completion
A4: Yellow cells are coder inputs. Complete MP first, then segment the same item in UCR Segmentation and confirm completion here. Timestamps must use ISO 8601 with a colon in the timezone offset.
A5: Blind item ID | B5: Topic | C5: MP label | D5: Error category | E5: Source-based rationale (≥10 chars) | F5: Confidence | G5: MP completed at | H5: UCR segmentation complete? | I5: UCR completed at | J5: MP row QA | K5: UCR item QA
A6: MD-001 | B6: Experience | C6: preserved | D6: none | E6: Draft content matches both source extracts in substance and sequence; I found no material mismatch. | F6: 3 | G6: 46244.609 | H6: Yes | I6: 46244.613 | J6: =IF(AND(OR(C6="preserved",C6="not_preserved",C6="uncertain"),OR(D6="none",D6="added meaning",D6="omitted meaning",D6="contradicted meaning",D6="source ambiguity",D6="other"),OR(AND(C6="preserved",D6="none"),AND(C6="not_preserved",D6<>"none"),AND(C6="uncertain",OR(D6="source ambiguity",D6="other"))),LEN(TRIM(E6))>=10,OR(F6=1,F6=2,F6=3),OR(AND(ISNUMBER(G6),G6>=DATE(2020,1,1)),IFERROR(AND(LEN(G6)>=20,ISNUMBER(SEARCH("T",G6)),OR(RIGHT(G6,1)="Z",MID(G6,LEN(G6)-5,1)="+",MID(G6,LEN(G6)-5,1)="-")),FALSE))),"PASS","INCOMPLETE") -> PASS | K6: =IF(AND(H6="Yes",OR(AND(ISNUMBER(I6),I6>=DATE(2020,1,1)),IFERROR(AND(LEN(I6)>=20,ISNUMBER(SEARCH("T",I6)),OR(RIGHT(I6,1)="Z",MID(I6,LEN(I6)-5,1)="+",MID(I6,LEN(I6)-5,1)="-")),FALSE)),COUNTA('UCR Segmentation'!$C$6:$C$17)>=1,COUNTIF('UCR Segmentation'!$D$6:$D$17,"GAP")=0),"PASS","INCOMPLETE") -> PASS
A7: MD-002 | B7: Experience | C7: preserved | D7: none | E7: Both statements correspond directly to the source, including that no further detail was remembered. | F7: 3 | G7: 46244.615 | H7: Yes | I7: 46244.617 | J7: =IF(AND(OR(C7="preserved",C7="not_preserved",C7="uncertain"),OR(D7="none",D7="added meaning",D7="omitted meaning",D7="contradicted meaning",D7="source ambiguity",D7="other"),OR(AND(C7="preserved",D7="none"),AND(C7="not_preserved",D7<>"none"),AND(C7="uncertain",OR(D7="source ambiguity",D7="other"))),LEN(TRIM(E7))>=10,OR(F7=1,F7=2,F7=3),OR(AND(ISNUMBER(G7),G7>=DATE(2020,1,1)),IFERROR(AND(LEN(G7)>=20,ISNUMBER(SEARCH("T",G7)),OR(RIGHT(G7,1)="Z",MID(G7,LEN(G7)-5,1)="+",MID(G7,LEN(G7)-5,1)="-")),FALSE))),"PASS","INCOMPLETE") -> PASS | K7: =IF(AND(H7="Yes",OR(AND(ISNUMBER(I7),I7>=DATE(2020,1,1)),IFERROR(AND(LEN(I7)>=20,ISNUMBER(SEARCH("T",I7)),OR(RIGHT(I7,1)="Z",MID(I7,LEN(I7)-5,1)="+",MID(I7,LEN(I7)-5,1)="-")),FALSE)),COUNTA('UCR Segmentation'!$C$18:$C$29)>=1,COUNTIF('UCR Segmentation'!$D$18:$D$29,"GAP")=0),"PASS","INCOMPLETE") -> PASS
A8: MD-003 | B8: Experience | C8: preserved | D8: none | E8: Content is materially identical to the source, including the train stop, alarms, and reported response to noise and lack of space. | F8: 3 | G8: 46244.62 | H8: Yes | I8: 46244.624 | J8: =IF(AND(OR(C8="preserved",C8="not_preserved",C8="uncertain"),OR(D8="none",D8="added meaning",D8="omitted meaning",D8="contradicted meaning",D8="source ambiguity",D8="other"),OR(AND(C8="preserved",D8="none"),AND(C8="not_preserved",D8<>"none"),AND(C8="uncertain",OR(D8="source ambiguity",D8="other"))),LEN(TRIM(E8))>=10,OR(F8=1,F8=2,F8=3),OR(AND(ISNUMBER(G8),G8>=DATE(2020,1,1)),IFERROR(AND(LEN(G8)>=20,ISNUMBER(SEARCH("T",G8)),OR(RIGHT(G8,1)="Z",MID(G8,LEN(G8)-5,1)="+",MID(G8,LEN(G8)-5,1)="-")),FALSE))),"PASS","INCOMPLETE") -> PASS | K8: =IF(AND(H8="Yes",OR(AND(ISNUMBER(I8),I8>=DATE(2020,1,1)),IFERROR(AND(LEN(I8)>=20,ISNUMBER(SEARCH("T",I8)),OR(RIGHT(I8,1)="Z",MID(I8,LEN(I8)-5,1)="+",MID(I8,LEN(I8)-5,1)="-")),FALSE)),COUNTA('UCR Segmentation'!$C$30:$C$41)>=1,COUNTIF('UCR Segmentation'!$D$30:$D$41,"GAP")=0),"PASS","INCOMPLETE") -> PASS
A9: MD-004 | B9: Support concept reaction | C9: preserved | D9: none | E9: All four design-reaction points retain the same meaning and level of uncertainty as the source. | F9: 3 | G9: 46244.626 | H9: Yes | I9: 46244.629 | J9: =IF(AND(OR(C9="preserved",C9="not_preserved",C9="uncertain"),OR(D9="none",D9="added meaning",D9="omitted meaning",D9="contradicted meaning",D9="source ambiguity",D9="other"),OR(AND(C9="preserved",D9="none"),AND(C9="not_preserved",D9<>"none"),AND(C9="uncertain",OR(D9="source ambiguity",D9="other"))),LEN(TRIM(E9))>=10,OR(F9=1,F9=2,F9=3),OR(AND(ISNUMBER(G9),G9>=DATE(2020,1,1)),IFERROR(AND(LEN(G9)>=20,ISNUMBER(SEARCH("T",G9)),OR(RIGHT(G9,1)="Z",MID(G9,LEN(G9)-5,1)="+",MID(G9,LEN(G9)-5,1)="-")),FALSE))),"PASS","INCOMPLETE") -> PASS | K9: =IF(AND(H9="Yes",OR(AND(ISNUMBER(I9),I9>=DATE(2020,1,1)),IFERROR(AND(LEN(I9)>=20,ISNUMBER(SEARCH("T",I9)),OR(RIGHT(I9,1)="Z",MID(I9,LEN(I9)-5,1)="+",MID(I9,LEN(I9)-5,1)="-")),FALSE)),COUNTA('UCR Segmentation'!$C$42:$C$53)>=1,COUNTIF('UCR Segmentation'!$D$42:$D$53,"GAP")=0),"PASS","INCOMPLETE") -> PASS
A10: MD-005 | B10: Coping & support | C10: preserved | D10: none | E10: The draft carries over the coping actions, helpful alternatives, and the stated reason the announcements were unhelpful. | F10: 3 | G10: 46244.631 | H10: Yes | I10: 46244.634 | J10: =IF(AND(OR(C10="preserved",C10="not_preserved",C10="uncertain"),OR(D10="none",D10="added meaning",D10="omitted meaning",D10="contradicted meaning",D10="source ambiguity",D10="other"),OR(AND(C10="preserved",D10="none"),AND(C10="not_preserved",D10<>"none"),AND(C10="uncertain",OR(D10="source ambiguity",D10="other"))),LEN(TRIM(E10))>=10,OR(F10=1,F10=2,F10=3),OR(AND(ISNUMBER(G10),G10>=DATE(2020,1,1)),IFERROR(AND(LEN(G10)>=20,ISNUMBER(SEARCH("T",G10)),OR(RIGHT(G10,1)="Z",MID(G10,LEN(G10)-5,1)="+",MID(G10,LEN(G10)-5,1)="-")),FALSE))),"PASS","INCOMPLETE") -> PASS | K10: =IF(AND(H10="Yes",OR(AND(ISNUMBER(I10),I10>=DATE(2020,1,1)),IFERROR(AND(LEN(I10)>=20,ISNUMBER(SEARCH("T",I10)),OR(RIGHT(I10,1)="Z",MID(I10,LEN(I10)-5,1)="+",MID(I10,LEN(I10)-5,1)="-")),FALSE)),COUNTA('UCR Segmentation'!$C$54:$C$65)>=1,COUNTIF('UCR Segmentation'!$D$54:$D$65,"GAP")=0),"PASS","INCOMPLETE") -> PASS
A11: MD-006 | B11: Experience | C11: preserved | D11: none | E11: The account is consistent with the source on location, stop, alarms, crowding, and the reported effects. | F11: 3 | G11: 46244.635 | H11: Yes | I11: 46244.638 | J11: =IF(AND(OR(C11="preserved",C11="not_preserved",C11="uncertain"),OR(D11="none",D11="added meaning",D11="omitted meaning",D11="contradicted meaning",D11="source ambiguity",D11="other"),OR(AND(C11="preserved",D11="none"),AND(C11="not_preserved",D11<>"none"),AND(C11="uncertain",OR(D11="source ambiguity",D11="other"))),LEN(TRIM(E11))>=10,OR(F11=1,F11=2,F11=3),OR(AND(ISNUMBER(G11),G11>=DATE(2020,1,1)),IFERROR(AND(LEN(G11)>=20,ISNUMBER(SEARCH("T",G11)),OR(RIGHT(G11,1)="Z",MID(G11,LEN(G11)-5,1)="+",MID(G11,LEN(G11)-5,1)="-")),FALSE))),"PASS","INCOMPLETE") -> PASS | K11: =IF(AND(H11="Yes",OR(AND(ISNUMBER(I11),I11>=DATE(2020,1,1)),IFERROR(AND(LEN(I11)>=20,ISNUMBER(SEARCH("T",I11)),OR(RIGHT(I11,1)="Z",MID(I11,LEN(I11)-5,1)="+",MID(I11,LEN(I11)-5,1)="-")),FALSE)),COUNTA('UCR Segmentation'!$C$66:$C$77)>=1,COUNTIF('UCR Segmentation'!$D$66:$D$77,"GAP")=0),"PASS","INCOMPLETE") -> PASS
A12: MD-007 | B12: Triggers & signs | C12: preserved | D12: none | E12: Trigger types and the three reported responses match the source with no added interpretation. | F12: 3 | G12: 46244.64 | H12: Yes | I12: 46244.642 | J12: =IF(AND(OR(C12="preserved",C12="not_preserved",C12="uncertain"),OR(D12="none",D12="added meaning",D12="omitted meaning",D12="contradicted meaning",D12="source ambiguity",D12="other"),OR(AND(C12="preserved",D12="none"),AND(C12="not_preserved",D12<>"none"),AND(C12="uncertain",OR(D12="source ambiguity",D12="other"))),LEN(TRIM(E12))>=10,OR(F12=1,F12=2,F12=3),OR(AND(ISNUMBER(G12),G12>=DATE(2020,1,1)),IFERROR(AND(LEN(G12)>=20,ISNUMBER(SEARCH("T",G12)),OR(RIGHT(G12,1)="Z",MID(G12,LEN(G12)-5,1)="+",MID(G12,LEN(G12)-5,1)="-")),FALSE))),"PASS","INCOMPLETE") -> PASS | K12: =IF(AND(H12="Yes",OR(AND(ISNUMBER(I12),I12>=DATE(2020,1,1)),IFERROR(AND(LEN(I12)>=20,ISNUMBER(SEARCH("T",I12)),OR(RIGHT(I12,1)="Z",MID(I12,LEN(I12)-5,1)="+",MID(I12,LEN(I12)-5,1)="-")),FALSE)),COUNTA('UCR Segmentation'!$C$78:$C$89)>=1,COUNTIF('UCR Segmentation'!$D$78:$D$89,"GAP")=0),"PASS","INCOMPLETE") -> PASS
A13: MD-008 | B13: Experience | C13: preserved | D13: none | E13: The draft preserves the event timing and context as well as the combined-noise-and-crowding explanation. | F13: 3 | G13: 46244.645 | H13: Yes | I13: 46244.649 | J13: =IF(AND(OR(C13="preserved",C13="not_preserved",C13="uncertain"),OR(D13="none",D13="added meaning",D13="omitted meaning",D13="contradicted meaning",D13="source ambiguity",D13="other"),OR(AND(C13="preserved",D13="none"),AND(C13="not_preserved",D13<>"none"),AND(C13="uncertain",OR(D13="source ambiguity",D13="other"))),LEN(TRIM(E13))>=10,OR(F13=1,F13=2,F13=3),OR(AND(ISNUMBER(G13),G13>=DATE(2020,1,1)),IFERROR(AND(LEN(G13)>=20,ISNUMBER(SEARCH("T",G13)),OR(RIGHT(G13,1)="Z",MID(G13,LEN(G13)-5,1)="+",MID(G13,LEN(G13)-5,1)="-")),FALSE))),"PASS","INCOMPLETE") -> PASS | K13: =IF(AND(H13="Yes",OR(AND(ISNUMBER(I13),I13>=DATE(2020,1,1)),IFERROR(AND(LEN(I13)>=20,ISNUMBER(SEARCH("T",I13)),OR(RIGHT(I13,1)="Z",MID(I13,LEN(I13)-5,1)="+",MID(I13,LEN(I13)-5,1)="-")),FALSE)),COUNTA('UCR Segmentation'!$C$90:$C$101)>=1,COUNTIF('UCR Segmentation'!$D$90:$D$101,"GAP")=0),"PASS","INCOMPLETE") -> PASS
A14: MD-009 | B14: Public-use acceptability | C14: preserved | D14: none | E14: The public-use conditions and concerns match the source; no substantive information is changed. | F14: 3 | G14: 46244.652 | H14: Yes | I14: 46244.654 | J14: =IF(AND(OR(C14="preserved",C14="not_preserved",C14="uncertain"),OR(D14="none",D14="added meaning",D14="omitted meaning",D14="contradicted meaning",D14="source ambiguity",D14="other"),OR(AND(C14="preserved",D14="none"),AND(C14="not_preserved",D14<>"none"),AND(C14="uncertain",OR(D14="source ambiguity",D14="other"))),LEN(TRIM(E14))>=10,OR(F14=1,F14=2,F14=3),OR(AND(ISNUMBER(G14),G14>=DATE(2020,1,1)),IFERROR(AND(LEN(G14)>=20,ISNUMBER(SEARCH("T",G14)),OR(RIGHT(G14,1)="Z",MID(G14,LEN(G14)-5,1)="+",MID(G14,LEN(G14)-5,1)="-")),FALSE))),"PASS","INCOMPLETE") -> PASS | K14: =IF(AND(H14="Yes",OR(AND(ISNUMBER(I14),I14>=DATE(2020,1,1)),IFERROR(AND(LEN(I14)>=20,ISNUMBER(SEARCH("T",I14)),OR(RIGHT(I14,1)="Z",MID(I14,LEN(I14)-5,1)="+",MID(I14,LEN(I14)-5,1)="-")),FALSE)),COUNTA('UCR Segmentation'!$C$102:$C$113)>=1,COUNTIF('UCR Segmentation'!$D$102:$D$113,"GAP")=0),"PASS","INCOMPLETE") -> PASS

Sheet UCR Segmentation
A1: UCR Phase 1 — independent atomic-proposition segmentation
A4: Enter the smallest independently supportable factual or experiential propositions. Start at 1, use consecutive rows without gaps, and leave all unused reserve rows blank. Do not enter supported/unsupported labels in Phase 1.
A5: Blind item ID | B5: Proposition index | C5: Atomic proposition | D5: Slot QA
A6: MD-001 | B6: 1 | C6: The event took place on a train. | D6: =IF(C6="","UNUSED",IF(COUNTA($C$6:C6)=B6,"USED","GAP")) -> USED
A7: MD-001 | B7: 2 | C7: The train was packed with people. | D7: =IF(C7="","UNUSED",IF(COUNTA($C$6:C7)=B7,"USED","GAP")) -> USED
A8: MD-001 | B8: 3 | C8: The train came to a sudden stop. | D8: =IF(C8="","UNUSED",IF(COUNTA($C$6:C8)=B8,"USED","GAP")) -> USED
A9: MD-001 | B9: 4 | C9: A loud screeching noise accompanied the stop. | D9: =IF(C9="","UNUSED",IF(COUNTA($C$6:C9)=B9,"USED","GAP")) -> USED
A10: MD-001 | B10: 5 | C10: The participant was unable to move away from the crowd. | D10: =IF(C10="","UNUSED",IF(COUNTA($C$6:C10)=B10,"USED","GAP")) -> USED
A11: MD-001 | B11: 6 | C11: The participant described feeling trapped. | D11: =IF(C11="","UNUSED",IF(COUNTA($C$6:C11)=B11,"USED","GAP")) -> USED
A12: MD-001 | B12: 7 | C12: The participant described feeling overwhelmed. | D12: =IF(C12="","UNUSED",IF(COUNTA($C$6:C12)=B12,"USED","GAP")) -> USED
A13: MD-001 | B13: 8 | D13: =IF(C13="","UNUSED",IF(COUNTA($C$6:C13)=B13,"USED","GAP")) -> UNUSED
A14: MD-001 | B14: 9 | D14: =IF(C14="","UNUSED",IF(COUNTA($C$6:C14)=B14,"USED","GAP")) -> UNUSED
A15: MD-001 | B15: 10 | D15: =IF(C15="","UNUSED",IF(COUNTA($C$6:C15)=B15,"USED","GAP")) -> UNUSED
A16: MD-001 | B16: 11 | D16: =IF(C16="","UNUSED",IF(COUNTA($C$6:C16)=B16,"USED","GAP")) -> UNUSED
A17: MD-001 | B17: 12 | D17: =IF(C17="","UNUSED",IF(COUNTA($C$6:C17)=B17,"USED","GAP")) -> UNUSED
A18: MD-002 | B18: 1 | C18: The event took place on a train. | D18: =IF(C18="","UNUSED",IF(COUNTA($C$18:C18)=B18,"USED","GAP")) -> USED
A19: MD-002 | B19: 2 | C19: The participant could not recall any further details about it. | D19: =IF(C19="","UNUSED",IF(COUNTA($C$18:C19)=B19,"USED","GAP")) -> USED
A20: MD-002 | B20: 3 | D20: =IF(C20="","UNUSED",IF(COUNTA($C$18:C20)=B20,"USED","GAP")) -> UNUSED
A21: MD-002 | B21: 4 | D21: =IF(C21="","UNUSED",IF(COUNTA($C$18:C21)=B21,"USED","GAP")) -> UNUSED
A22: MD-002 | B22: 5 | D22: =IF(C22="","UNUSED",IF(COUNTA($C$18:C22)=B22,"USED","GAP")) -> UNUSED
A23: MD-002 | B23: 6 | D23: =IF(C23="","UNUSED",IF(COUNTA($C$18:C23)=B23,"USED","GAP")) -> UNUSED
A24: MD-002 | B24: 7 | D24: =IF(C24="","UNUSED",IF(COUNTA($C$18:C24)=B24,"USED","GAP")) -> UNUSED
A25: MD-002 | B25: 8 | D25: =IF(C25="","UNUSED",IF(COUNTA($C$18:C25)=B25,"USED","GAP")) -> UNUSED
A26: MD-002 | B26: 9 | D26: =IF(C26="","UNUSED",IF(COUNTA($C$18:C26)=B26,"USED","GAP")) -> UNUSED
A27: MD-002 | B27: 10 | D27: =IF(C27="","UNUSED",IF(COUNTA($C$18:C27)=B27,"USED","GAP")) -> UNUSED
A28: MD-002 | B28: 11 | D28: =IF(C28="","UNUSED",IF(COUNTA($C$18:C28)=B28,"USED","GAP")) -> UNUSED
A29: MD-002 | B29: 12 | D29: =IF(C29="","UNUSED",IF(COUNTA($C$18:C29)=B29,"USED","GAP")) -> UNUSED
A30: MD-003 | B30: 1 | C30: The participant's example was on a crowded train. | D30: =IF(C30="","UNUSED",IF(COUNTA($C$30:C30)=B30,"USED","GAP")) -> USED
A31: MD-003 | B31: 2 | C31: The train stopped between stations. | D31: =IF(C31="","UNUSED",IF(COUNTA($C$30:C31)=B31,"USED","GAP")) -> USED
A32: MD-003 | B32: 3 | C32: Alarms were sounding at the time. | D32: =IF(C32="","UNUSED",IF(COUNTA($C$30:C32)=B32,"USED","GAP")) -> USED
A33: MD-003 | B33: 4 | C33: The combination of noise and limited space made the participant feel trapped. | D33: =IF(C33="","UNUSED",IF(COUNTA($C$30:C33)=B33,"USED","GAP")) -> USED
A34: MD-003 | B34: 5 | C34: The combination of noise and limited space made the participant feel overwhelmed. | D34: =IF(C34="","UNUSED",IF(COUNTA($C$30:C34)=B34,"USED","GAP")) -> USED
A35: MD-003 | B35: 6 | D35: =IF(C35="","UNUSED",IF(COUNTA($C$30:C35)=B35,"USED","GAP")) -> UNUSED
A36: MD-003 | B36: 7 | D36: =IF(C36="","UNUSED",IF(COUNTA($C$30:C36)=B36,"USED","GAP")) -> UNUSED
A37: MD-003 | B37: 8 | D37: =IF(C37="","UNUSED",IF(COUNTA($C$30:C37)=B37,"USED","GAP")) -> UNUSED
A38: MD-003 | B38: 9 | D38: =IF(C38="","UNUSED",IF(COUNTA($C$30:C38)=B38,"USED","GAP")) -> UNUSED
A39: MD-003 | B39: 10 | D39: =IF(C39="","UNUSED",IF(COUNTA($C$30:C39)=B39,"USED","GAP")) -> UNUSED
A40: MD-003 | B40: 11 | D40: =IF(C40="","UNUSED",IF(COUNTA($C$30:C40)=B40,"USED","GAP")) -> UNUSED
A41: MD-003 | B41: 12 | D41: =IF(C41="","UNUSED",IF(COUNTA($C$30:C41)=B41,"USED","GAP")) -> UNUSED
A42: MD-004 | B42: 1 | C42: The squeeze interaction was seen as useful because it would give the participant's hands something to focus on. | D42: =IF(C42="","UNUSED",IF(COUNTA($C$42:C42)=B42,"USED","GAP")) -> USED
...

Sheet QA Summary
A1: Formula QA summary — external validation remains authoritative
A4: Check | B4: Expected | C4: Observed | D4: Status | E4: Interpretation
A5: Blind materials | B5: 9 | C5: =COUNTA(Materials!$A$6:$A$14) -> 9 | D5: =IF(B5=C5,"PASS","INCOMPLETE") -> PASS | E5: Nine unique generated-draft/source bundles.
A6: MP complete rows | B6: 9 | C6: =COUNTIF('MP Coding'!$J$6:$J$14,"PASS") -> 9 | D6: =IF(B6=C6,"PASS","INCOMPLETE") -> PASS | E6: Every MP row requires label, compatible error category, rationale, confidence and timestamp.
A7: UCR items segmented | B7: 9 | C7: =COUNTIF('MP Coding'!$K$6:$K$14,"PASS") -> 9 | D7: =IF(B7=C7,"PASS","INCOMPLETE") -> PASS | E7: Every blind item requires ≥1 consecutive atomic proposition and item confirmation.
A8: Coder/declaration fields | B8: PASS | C8: ='Start Here'!$B$19 -> PASS | D8: =IF(B8=C8,"PASS","INCOMPLETE") -> PASS | E8: Identity, experience, declarations and timestamps are required.
A9: Overall Phase 1 QA | B9: PASS | C9: =IF(AND(D5="PASS",D6="PASS",D7="PASS",D8="PASS"),"PASS","INCOMPLETE") -> PASS | D9: =C9 -> PASS | E9: Return the workbook only when this row is PASS.
A12: Blind item | B12: Used propositions | C12: Gap rows | D12: Coder confirmed? | E12: Item QA
A13: MD-001 | B13: =COUNTA('UCR Segmentation'!$C$6:$C$17) -> 7 | C13: =COUNTIF('UCR Segmentation'!$D$6:$D$17,"GAP") -> 0 | D13: =IF('MP Coding'!$H$6="","",'MP Coding'!$H$6) -> Yes | E13: ='MP Coding'!$K$6 -> PASS
A14: MD-002 | B14: =COUNTA('UCR Segmentation'!$C$18:$C$29) -> 2 | C14: =COUNTIF('UCR Segmentation'!$D$18:$D$29,"GAP") -> 0 | D14: =IF('MP Coding'!$H$7="","",'MP Coding'!$H$7) -> Yes | E14: ='MP Coding'!$K$7 -> PASS
A15: MD-003 | B15: =COUNTA('UCR Segmentation'!$C$30:$C$41) -> 5 | C15: =COUNTIF('UCR Segmentation'!$D$30:$D$41,"GAP") -> 0 | D15: =IF('MP Coding'!$H$8="","",'MP Coding'!$H$8) -> Yes | E15: ='MP Coding'!$K$8 -> PASS
A16: MD-004 | B16: =COUNTA('UCR Segmentation'!$C$42:$C$53) -> 4 | C16: =COUNTIF('UCR Segmentation'!$D$42:$D$53,"GAP") -> 0 | D16: =IF('MP Coding'!$H$9="","",'MP Coding'!$H$9) -> Yes | E16: ='MP Coding'!$K$9 -> PASS
A17: MD-005 | B17: =COUNTA('UCR Segmentation'!$C$54:$C$65) -> 6 | C17: =COUNTIF('UCR Segmentation'!$D$54:$D$65,"GAP") -> 0 | D17: =IF('MP Coding'!$H$10="","",'MP Coding'!$H$10) -> Yes | E17: ='MP Coding'!$K$10 -> PASS
A18: MD-006 | B18: =COUNTA('UCR Segmentation'!$C$66:$C$77) -> 5 | C18: =COUNTIF('UCR Segmentation'!$D$66:$D$77,"GAP") -> 0 | D18: =IF('MP Coding'!$H$11="","",'MP Coding'!$H$11) -> Yes | E18: ='MP Coding'!$K$11 -> PASS
A19: MD-007 | B19: =COUNTA('UCR Segmentation'!$C$78:$C$89) -> 6 | C19: =COUNTIF('UCR Segmentation'!$D$78:$D$89,"GAP") -> 0 | D19: =IF('MP Coding'!$H$12="","",'MP Coding'!$H$12) -> Yes | E19: ='MP Coding'!$K$12 -> PASS
A20: MD-008 | B20: =COUNTA('UCR Segmentation'!$C$90:$C$101) -> 8 | C20: =COUNTIF('UCR Segmentation'!$D$90:$D$101,"GAP") -> 0 | D20: =IF('MP Coding'!$H$13="","",'MP Coding'!$H$13) -> Yes | E20: ='MP Coding'!$K$13 -> PASS
A21: MD-009 | B21: =COUNTA('UCR Segmentation'!$C$102:$C$113) -> 3 | C21: =COUNTIF('UCR Segmentation'!$D$102:$D$113,"GAP") -> 0 | D21: =IF('MP Coding'!$H$14="","",'MP Coding'!$H$14) -> Yes | E21: ='MP Coding'!$K$14 -> PASS
