Workbook

Sheet Start Here
A1: PurrStone v10.2 — Coder01 Phase 1 independent coding | B1: PurrStone v10.2 — Coder01 Phase 1 independent coding | C1: PurrStone v10.2 — Coder01 Phase 1 independent coding | D1: PurrStone v10.2 — Coder01 Phase 1 independent coding | E1: PurrStone v10.2 — Coder01 Phase 1 independent coding | F1: PurrStone v10.2 — Coder01 Phase 1 independent coding | G1: PurrStone v10.2 — Coder01 Phase 1 independent coding | H1: PurrStone v10.2 — Coder01 Phase 1 independent coding
A2: PurrStone v10.2 — Coder01 Phase 1 independent coding | B2: PurrStone v10.2 — Coder01 Phase 1 independent coding | C2: PurrStone v10.2 — Coder01 Phase 1 independent coding | D2: PurrStone v10.2 — Coder01 Phase 1 independent coding | E2: PurrStone v10.2 — Coder01 Phase 1 independent coding | F2: PurrStone v10.2 — Coder01 Phase 1 independent coding | G2: PurrStone v10.2 — Coder01 Phase 1 independent coding | H2: PurrStone v10.2 — Coder01 Phase 1 independent coding
A4: Complete every yellow field yourself. Identity/contact may be held separately by the administrator, but the workbook must retain a verifiable receipt code. | B4: Complete every yellow field yourself. Identity/contact may be held separately by the administrator, but the workbook must retain a verifiable receipt code. | C4: Complete every yellow field yourself. Identity/contact may be held separately by the administrator, but the workbook must retain a verifiable receipt code. | D4: Complete every yellow field yourself. Identity/contact may be held separately by the administrator, but the workbook must retain a verifiable receipt code. | E4: Complete every yellow field yourself. Identity/contact may be held separately by the administrator, but the workbook must retain a verifiable receipt code. | F4: Complete every yellow field yourself. Identity/contact may be held separately by the administrator, but the workbook must retain a verifiable receipt code. | G4: Complete every yellow field yourself. Identity/contact may be held separately by the administrator, but the workbook must retain a verifiable receipt code. | H4: Complete every yellow field yourself. Identity/contact may be held separately by the administrator, but the workbook must retain a verifiable receipt code.
A6: Package build ID | B6: purrstone-v10.2-pre-coder-q2-r1-20260809
A7: Assigned coder ID | B7: Coder01
A8: Verifier identity/contact held separately by administrator? | B8: Yes
A9: Role / relevant research or qualitative-coding experience | B9: MSc Design Engineering graduate with experience in semi-structured interviews, basic qualitative coding, and checking AI-generated summaries against source material.
A10: Coding protocol read in full? | B10: Yes
A11: I will work independently before consensus. | B11: Yes
A12: I will not seek the condition/item identity key. | B12: Yes
A13: Started at (ISO-8601 + timezone) | B13: 46243.565
A14: Completed at (ISO-8601 + timezone) | B14: 46243.635
A15: Typed name / pseudonymous signature | B15: Coder01
A16: Administrator-issued receipt code | B16: V102-P1-C01-K7M4
A19: Phase 1 formula QA | B19: ='QA Summary'!D12 -> PASS
A21: Workflow boundary: this Phase 1 workbook contains formal A/B scoring, supplementary MP coding, and supplementary UCR proposition segmentation. UCR support labels are intentionally absent. After both segmentations are locked, a common blind inventory will be frozen and issued in separate Phase 2 label workbooks. Do not perform consensus or unblinding in this file. | B21: Workflow boundary: this Phase 1 workbook contains formal A/B scoring, supplementary MP coding, and supplementary UCR proposition segmentation. UCR support labels are intentionally absent. After both segmentations are locked, a common blind inventory will be frozen and issued in separate Phase 2 label workbooks. Do not perform consensus or unblinding in this file. | C21: Workflow boundary: this Phase 1 workbook contains formal A/B scoring, supplementary MP coding, and supplementary UCR proposition segmentation. UCR support labels are intentionally absent. After both segmentations are locked, a common blind inventory will be frozen and issued in separate Phase 2 label workbooks. Do not perform consensus or unblinding in this file. | D21: Workflow boundary: this Phase 1 workbook contains formal A/B scoring, supplementary MP coding, and supplementary UCR proposition segmentation. UCR support labels are intentionally absent. After both segmentations are locked, a common blind inventory will be frozen and issued in separate Phase 2 label workbooks. Do not perform consensus or unblinding in this file. | E21: Workflow boundary: this Phase 1 workbook contains formal A/B scoring, supplementary MP coding, and supplementary UCR proposition segmentation. UCR support labels are intentionally absent. After both segmentations are locked, a common blind inventory will be frozen and issued in separate Phase 2 label workbooks. Do not perform consensus or unblinding in this file. | F21: Workflow boundary: this Phase 1 workbook contains formal A/B scoring, supplementary MP coding, and supplementary UCR proposition segmentation. UCR support labels are intentionally absent. After both segmentations are locked, a common blind inventory will be frozen and issued in separate Phase 2 label workbooks. Do not perform consensus or unblinding in this file. | G21: Workflow boundary: this Phase 1 workbook contains formal A/B scoring, supplementary MP coding, and supplementary UCR proposition segmentation. UCR support labels are intentionally absent. After both segmentations are locked, a common blind inventory will be frozen and issued in separate Phase 2 label workbooks. Do not perform consensus or unblinding in this file. | H21: Workflow boundary: this Phase 1 workbook contains formal A/B scoring, supplementary MP coding, and supplementary UCR proposition segmentation. UCR support labels are intentionally absent. After both segmentations are locked, a common blind inventory will be frozen and issued in separate Phase 2 label workbooks. Do not perform consensus or unblinding in this file.
A22: Workflow boundary: this Phase 1 workbook contains formal A/B scoring, supplementary MP coding, and supplementary UCR proposition segmentation. UCR support labels are intentionally absent. After both segmentations are locked, a common blind inventory will be frozen and issued in separate Phase 2 label workbooks. Do not perform consensus or unblinding in this file. | B22: Workflow boundary: this Phase 1 workbook contains formal A/B scoring, supplementary MP coding, and supplementary UCR proposition segmentation. UCR support labels are intentionally absent. After both segmentations are locked, a common blind inventory will be frozen and issued in separate Phase 2 label workbooks. Do not perform consensus or unblinding in this file. | C22: Workflow boundary: this Phase 1 workbook contains formal A/B scoring, supplementary MP coding, and supplementary UCR proposition segmentation. UCR support labels are intentionally absent. After both segmentations are locked, a common blind inventory will be frozen and issued in separate Phase 2 label workbooks. Do not perform consensus or unblinding in this file. | D22: Workflow boundary: this Phase 1 workbook contains formal A/B scoring, supplementary MP coding, and supplementary UCR proposition segmentation. UCR support labels are intentionally absent. After both segmentations are locked, a common blind inventory will be frozen and issued in separate Phase 2 label workbooks. Do not perform consensus or unblinding in this file. | E22: Workflow boundary: this Phase 1 workbook contains formal A/B scoring, supplementary MP coding, and supplementary UCR proposition segmentation. UCR support labels are intentionally absent. After both segmentations are locked, a common blind inventory will be frozen and issued in separate Phase 2 label workbooks. Do not perform consensus or unblinding in this file. | F22: Workflow boundary: this Phase 1 workbook contains formal A/B scoring, supplementary MP coding, and supplementary UCR proposition segmentation. UCR support labels are intentionally absent. After both segmentations are locked, a common blind inventory will be frozen and issued in separate Phase 2 label workbooks. Do not perform consensus or unblinding in this file. | G22: Workflow boundary: this Phase 1 workbook contains formal A/B scoring, supplementary MP coding, and supplementary UCR proposition segmentation. UCR support labels are intentionally absent. After both segmentations are locked, a common blind inventory will be frozen and issued in separate Phase 2 label workbooks. Do not perform consensus or unblinding in this file. | H22: Workflow boundary: this Phase 1 workbook contains formal A/B scoring, supplementary MP coding, and supplementary UCR proposition segmentation. UCR support labels are intentionally absent. After both segmentations are locked, a common blind inventory will be frozen and issued in separate Phase 2 label workbooks. Do not perform consensus or unblinding in this file.
A23: Workflow boundary: this Phase 1 workbook contains formal A/B scoring, supplementary MP coding, and supplementary UCR proposition segmentation. UCR support labels are intentionally absent. After both segmentations are locked, a common blind inventory will be frozen and issued in separate Phase 2 label workbooks. Do not perform consensus or unblinding in this file. | B23: Workflow boundary: this Phase 1 workbook contains formal A/B scoring, supplementary MP coding, and supplementary UCR proposition segmentation. UCR support labels are intentionally absent. After both segmentations are locked, a common blind inventory will be frozen and issued in separate Phase 2 label workbooks. Do not perform consensus or unblinding in this file. | C23: Workflow boundary: this Phase 1 workbook contains formal A/B scoring, supplementary MP coding, and supplementary UCR proposition segmentation. UCR support labels are intentionally absent. After both segmentations are locked, a common blind inventory will be frozen and issued in separate Phase 2 label workbooks. Do not perform consensus or unblinding in this file. | D23: Workflow boundary: this Phase 1 workbook contains formal A/B scoring, supplementary MP coding, and supplementary UCR proposition segmentation. UCR support labels are intentionally absent. After both segmentations are locked, a common blind inventory will be frozen and issued in separate Phase 2 label workbooks. Do not perform consensus or unblinding in this file. | E23: Workflow boundary: this Phase 1 workbook contains formal A/B scoring, supplementary MP coding, and supplementary UCR proposition segmentation. UCR support labels are intentionally absent. After both segmentations are locked, a common blind inventory will be frozen and issued in separate Phase 2 label workbooks. Do not perform consensus or unblinding in this file. | F23: Workflow boundary: this Phase 1 workbook contains formal A/B scoring, supplementary MP coding, and supplementary UCR proposition segmentation. UCR support labels are intentionally absent. After both segmentations are locked, a common blind inventory will be frozen and issued in separate Phase 2 label workbooks. Do not perform consensus or unblinding in this file. | G23: Workflow boundary: this Phase 1 workbook contains formal A/B scoring, supplementary MP coding, and supplementary UCR proposition segmentation. UCR support labels are intentionally absent. After both segmentations are locked, a common blind inventory will be frozen and issued in separate Phase 2 label workbooks. Do not perform consensus or unblinding in this file. | H23: Workflow boundary: this Phase 1 workbook contains formal A/B scoring, supplementary MP coding, and supplementary UCR proposition segmentation. UCR support labels are intentionally absent. After both segmentations are locked, a common blind inventory will be frozen and issued in separate Phase 2 label workbooks. Do not perform consensus or unblinding in this file.
A24: Workflow boundary: this Phase 1 workbook contains formal A/B scoring, supplementary MP coding, and supplementary UCR proposition segmentation. UCR support labels are intentionally absent. After both segmentations are locked, a common blind inventory will be frozen and issued in separate Phase 2 label workbooks. Do not perform consensus or unblinding in this file. | B24: Workflow boundary: this Phase 1 workbook contains formal A/B scoring, supplementary MP coding, and supplementary UCR proposition segmentation. UCR support labels are intentionally absent. After both segmentations are locked, a common blind inventory will be frozen and issued in separate Phase 2 label workbooks. Do not perform consensus or unblinding in this file. | C24: Workflow boundary: this Phase 1 workbook contains formal A/B scoring, supplementary MP coding, and supplementary UCR proposition segmentation. UCR support labels are intentionally absent. After both segmentations are locked, a common blind inventory will be frozen and issued in separate Phase 2 label workbooks. Do not perform consensus or unblinding in this file. | D24: Workflow boundary: this Phase 1 workbook contains formal A/B scoring, supplementary MP coding, and supplementary UCR proposition segmentation. UCR support labels are intentionally absent. After both segmentations are locked, a common blind inventory will be frozen and issued in separate Phase 2 label workbooks. Do not perform consensus or unblinding in this file. | E24: Workflow boundary: this Phase 1 workbook contains formal A/B scoring, supplementary MP coding, and supplementary UCR proposition segmentation. UCR support labels are intentionally absent. After both segmentations are locked, a common blind inventory will be frozen and issued in separate Phase 2 label workbooks. Do not perform consensus or unblinding in this file. | F24: Workflow boundary: this Phase 1 workbook contains formal A/B scoring, supplementary MP coding, and supplementary UCR proposition segmentation. UCR support labels are intentionally absent. After both segmentations are locked, a common blind inventory will be frozen and issued in separate Phase 2 label workbooks. Do not perform consensus or unblinding in this file. | G24: Workflow boundary: this Phase 1 workbook contains formal A/B scoring, supplementary MP coding, and supplementary UCR proposition segmentation. UCR support labels are intentionally absent. After both segmentations are locked, a common blind inventory will be frozen and issued in separate Phase 2 label workbooks. Do not perform consensus or unblinding in this file. | H24: Workflow boundary: this Phase 1 workbook contains formal A/B scoring, supplementary MP coding, and supplementary UCR proposition segmentation. UCR support labels are intentionally absent. After both segmentations are locked, a common blind inventory will be frozen and issued in separate Phase 2 label workbooks. Do not perform consensus or unblinding in this file.

Sheet A-B Coding
A1: Part A — Formal blinded A/B output-quality coding (10 complete pairs) | B1: Part A — Formal blinded A/B output-quality coding (10 complete pairs) | C1: Part A — Formal blinded A/B output-quality coding (10 complete pairs) | D1: Part A — Formal blinded A/B output-quality coding (10 complete pairs) | E1: Part A — Formal blinded A/B output-quality coding (10 complete pairs) | F1: Part A — Formal blinded A/B output-quality coding (10 complete pairs) | G1: Part A — Formal blinded A/B output-quality coding (10 complete pairs) | H1: Part A — Formal blinded A/B output-quality coding (10 complete pairs) | I1: Part A — Formal blinded A/B output-quality coding (10 complete pairs) | J1: Part A — Formal blinded A/B output-quality coding (10 complete pairs) | K1: Part A — Formal blinded A/B output-quality coding (10 complete pairs) | L1: Part A — Formal blinded A/B output-quality coding (10 complete pairs) | M1: Part A — Formal blinded A/B output-quality coding (10 complete pairs) | N1: Part A — Formal blinded A/B output-quality coding (10 complete pairs) | O1: Part A — Formal blinded A/B output-quality coding (10 complete pairs) | P1: Part A — Formal blinded A/B output-quality coding (10 complete pairs) | Q1: Part A — Formal blinded A/B output-quality coding (10 complete pairs) | R1: Part A — Formal blinded A/B output-quality coding (10 complete pairs) | S1: Part A — Formal blinded A/B output-quality coding (10 complete pairs) | T1: Part A — Formal blinded A/B output-quality coding (10 complete pairs) | U1: Part A — Formal blinded A/B output-quality coding (10 complete pairs) | V1: Part A — Formal blinded A/B output-quality coding (10 complete pairs)
A2: Part A — Formal blinded A/B output-quality coding (10 complete pairs) | B2: Part A — Formal blinded A/B output-quality coding (10 complete pairs) | C2: Part A — Formal blinded A/B output-quality coding (10 complete pairs) | D2: Part A — Formal blinded A/B output-quality coding (10 complete pairs) | E2: Part A — Formal blinded A/B output-quality coding (10 complete pairs) | F2: Part A — Formal blinded A/B output-quality coding (10 complete pairs) | G2: Part A — Formal blinded A/B output-quality coding (10 complete pairs) | H2: Part A — Formal blinded A/B output-quality coding (10 complete pairs) | I2: Part A — Formal blinded A/B output-quality coding (10 complete pairs) | J2: Part A — Formal blinded A/B output-quality coding (10 complete pairs) | K2: Part A — Formal blinded A/B output-quality coding (10 complete pairs) | L2: Part A — Formal blinded A/B output-quality coding (10 complete pairs) | M2: Part A — Formal blinded A/B output-quality coding (10 complete pairs) | N2: Part A — Formal blinded A/B output-quality coding (10 complete pairs) | O2: Part A — Formal blinded A/B output-quality coding (10 complete pairs) | P2: Part A — Formal blinded A/B output-quality coding (10 complete pairs) | Q2: Part A — Formal blinded A/B output-quality coding (10 complete pairs) | R2: Part A — Formal blinded A/B output-quality coding (10 complete pairs) | S2: Part A — Formal blinded A/B output-quality coding (10 complete pairs) | T2: Part A — Formal blinded A/B output-quality coding (10 complete pairs) | U2: Part A — Formal blinded A/B output-quality coding (10 complete pairs) | V2: Part A — Formal blinded A/B output-quality coding (10 complete pairs)
A3: Scores: 1=very poor, 5=very strong. Q2 is scored only when at least one material contains a missing-information follow-up probe. It is prefilled N/A for ordinary primary questions, Skip/Stop handling, boundary responses, and pairs with no probe. Do not alter metadata or rule mapping. | B3: Scores: 1=very poor, 5=very strong. Q2 is scored only when at least one material contains a missing-information follow-up probe. It is prefilled N/A for ordinary primary questions, Skip/Stop handling, boundary responses, and pairs with no probe. Do not alter metadata or rule mapping. | C3: Scores: 1=very poor, 5=very strong. Q2 is scored only when at least one material contains a missing-information follow-up probe. It is prefilled N/A for ordinary primary questions, Skip/Stop handling, boundary responses, and pairs with no probe. Do not alter metadata or rule mapping. | D3: Scores: 1=very poor, 5=very strong. Q2 is scored only when at least one material contains a missing-information follow-up probe. It is prefilled N/A for ordinary primary questions, Skip/Stop handling, boundary responses, and pairs with no probe. Do not alter metadata or rule mapping. | E3: Scores: 1=very poor, 5=very strong. Q2 is scored only when at least one material contains a missing-information follow-up probe. It is prefilled N/A for ordinary primary questions, Skip/Stop handling, boundary responses, and pairs with no probe. Do not alter metadata or rule mapping. | F3: Scores: 1=very poor, 5=very strong. Q2 is scored only when at least one material contains a missing-information follow-up probe. It is prefilled N/A for ordinary primary questions, Skip/Stop handling, boundary responses, and pairs with no probe. Do not alter metadata or rule mapping. | G3: Scores: 1=very poor, 5=very strong. Q2 is scored only when at least one material contains a missing-information follow-up probe. It is prefilled N/A for ordinary primary questions, Skip/Stop handling, boundary responses, and pairs with no probe. Do not alter metadata or rule mapping. | H3: Scores: 1=very poor, 5=very strong. Q2 is scored only when at least one material contains a missing-information follow-up probe. It is prefilled N/A for ordinary primary questions, Skip/Stop handling, boundary responses, and pairs with no probe. Do not alter metadata or rule mapping. | I3: Scores: 1=very poor, 5=very strong. Q2 is scored only when at least one material contains a missing-information follow-up probe. It is prefilled N/A for ordinary primary questions, Skip/Stop handling, boundary responses, and pairs with no probe. Do not alter metadata or rule mapping. | J3: Scores: 1=very poor, 5=very strong. Q2 is scored only when at least one material contains a missing-information follow-up probe. It is prefilled N/A for ordinary primary questions, Skip/Stop handling, boundary responses, and pairs with no probe. Do not alter metadata or rule mapping. | K3: Scores: 1=very poor, 5=very strong. Q2 is scored only when at least one material contains a missing-information follow-up probe. It is prefilled N/A for ordinary primary questions, Skip/Stop handling, boundary responses, and pairs with no probe. Do not alter metadata or rule mapping. | L3: Scores: 1=very poor, 5=very strong. Q2 is scored only when at least one material contains a missing-information follow-up probe. It is prefilled N/A for ordinary primary questions, Skip/Stop handling, boundary responses, and pairs with no probe. Do not alter metadata or rule mapping. | M3: Scores: 1=very poor, 5=very strong. Q2 is scored only when at least one material contains a missing-information follow-up probe. It is prefilled N/A for ordinary primary questions, Skip/Stop handling, boundary responses, and pairs with no probe. Do not alter metadata or rule mapping. | N3: Scores: 1=very poor, 5=very strong. Q2 is scored only when at least one material contains a missing-information follow-up probe. It is prefilled N/A for ordinary primary questions, Skip/Stop handling, boundary responses, and pairs with no probe. Do not alter metadata or rule mapping. | O3: Scores: 1=very poor, 5=very strong. Q2 is scored only when at least one material contains a missing-information follow-up probe. It is prefilled N/A for ordinary primary questions, Skip/Stop handling, boundary responses, and pairs with no probe. Do not alter metadata or rule mapping. | P3: Scores: 1=very poor, 5=very strong. Q2 is scored only when at least one material contains a missing-information follow-up probe. It is prefilled N/A for ordinary primary questions, Skip/Stop handling, boundary responses, and pairs with no probe. Do not alter metadata or rule mapping. | Q3: Scores: 1=very poor, 5=very strong. Q2 is scored only when at least one material contains a missing-information follow-up probe. It is prefilled N/A for ordinary primary questions, Skip/Stop handling, boundary responses, and pairs with no probe. Do not alter metadata or rule mapping. | R3: Scores: 1=very poor, 5=very strong. Q2 is scored only when at least one material contains a missing-information follow-up probe. It is prefilled N/A for ordinary primary questions, Skip/Stop handling, boundary responses, and pairs with no probe. Do not alter metadata or rule mapping. | S3: Scores: 1=very poor, 5=very strong. Q2 is scored only when at least one material contains a missing-information follow-up probe. It is prefilled N/A for ordinary primary questions, Skip/Stop handling, boundary responses, and pairs with no probe. Do not alter metadata or rule mapping. | T3: Scores: 1=very poor, 5=very strong. Q2 is scored only when at least one material contains a missing-information follow-up probe. It is prefilled N/A for ordinary primary questions, Skip/Stop handling, boundary responses, and pairs with no probe. Do not alter metadata or rule mapping. | U3: Scores: 1=very poor, 5=very strong. Q2 is scored only when at least one material contains a missing-information follow-up probe. It is prefilled N/A for ordinary primary questions, Skip/Stop handling, boundary responses, and pairs with no probe. Do not alter metadata or rule mapping. | V3: Scores: 1=very poor, 5=very strong. Q2 is scored only when at least one material contains a missing-information follow-up probe. It is prefilled N/A for ordinary primary questions, Skip/Stop handling, boundary responses, and pairs with no probe. Do not alter metadata or rule mapping.
A5: Review package ID | B5: Blind pair ID | C5: Coder ID | D5: Q2 mode | E5: Material file | F5: A Q1 | G5: B Q1 | H5: A Q2 | I5: B Q2 | J5: A Q3 | K5: B Q3 | L5: A Q4 | M5: B Q4 | N5: A Q5 | O5: B Q5 | P5: Overall preference | Q5: Confidence | R5: Short rationale (≥10 chars) | S5: Issue flags JSON | T5: Completed at | U5: Row QA | V5: Rule-map QA
A6: purrstone-v10.2-pre-coder-q2-r1-20260809 | B6: BP-001 | C6: Coder01 | D6: BOTH_NA_REQUIRED | E6: materials/ab/pairs/BP-001.html | F6: 5 | G6: 5 | H6: N/A | I6: N/A | J6: 5 | K6: 5 | L6: 5 | M6: 4 | N6: 5 | O6: 5 | P6: A | Q6: 3 | R6: Both remain within the design-research boundary and the evidence is fully grounded. A is stronger on participant control because the boundary response explicitly reminds the participant that Skip and Stop remain available. | S6: ["B_control_reminder_less_explicit"] | T6: 46243.569 | U6: =IF(AND($A6<>"",$B6<>"",$C6<>"",ISNUMBER($F6),ISNUMBER($G6),ISNUMBER($J6),ISNUMBER($K6),ISNUMBER($L6),ISNUMBER($M6),ISNUMBER($N6),ISNUMBER($O6),OR(AND($D6="BOTH_NA_REQUIRED",$H6="N/A",$I6="N/A"),AND($D6="BOTH_SCORED_REQUIRED",ISNUMBER($H6),ISNUMBER($I6))),OR($P6="A",$P6="B",$P6="Tie"),ISNUMBER($Q6),LEN(TRIM($R6))>=10,LEFT(TRIM($S6),1)="[",RIGHT(TRIM($S6),1)="]",$T6<>""),"PASS","INCOMPLETE") -> PASS | V6: =IF(AND($B6='QA Rules'!$B$3,$D6='QA Rules'!$C$3),"PASS","RULE_ERROR") -> PASS
A7: purrstone-v10.2-pre-coder-q2-r1-20260809 | B7: BP-002 | C7: Coder01 | D7: BOTH_SCORED_REQUIRED | E7: materials/ab/pairs/BP-002.html | F7: 4 | G7: 4 | H7: 4 | I7: 5 | J7: 5 | K7: 5 | L7: 5 | M7: 3 | N7: 5 | O7: 4 | P7: A | Q7: 3 | R7: B's probe names both missing elements a little more directly, but A has the stronger overall flow: after the failed probe it actually asks the triggers question, whereas B moves on without asking it before the triggers answer appears. | S7: ["B_transition_missing_trigger_question"] | T7: 46243.573 | U7: =IF(AND($A7<>"",$B7<>"",$C7<>"",ISNUMBER($F7),ISNUMBER($G7),ISNUMBER($J7),ISNUMBER($K7),ISNUMBER($L7),ISNUMBER($M7),ISNUMBER($N7),ISNUMBER($O7),OR(AND($D7="BOTH_NA_REQUIRED",$H7="N/A",$I7="N/A"),AND($D7="BOTH_SCORED_REQUIRED",ISNUMBER($H7),ISNUMBER($I7))),OR($P7="A",$P7="B",$P7="Tie"),ISNUMBER($Q7),LEN(TRIM($R7))>=10,LEFT(TRIM($S7),1)="[",RIGHT(TRIM($S7),1)="]",$T7<>""),"PASS","INCOMPLETE") -> PASS | V7: =IF(AND($B7='QA Rules'!$B$4,$D7='QA Rules'!$C$4),"PASS","RULE_ERROR") -> PASS
A8: purrstone-v10.2-pre-coder-q2-r1-20260809 | B8: BP-003 | C8: Coder01 | D8: BOTH_SCORED_REQUIRED | E8: materials/ab/pairs/BP-003.html | F8: 4 | G8: 4 | H8: 5 | I8: 4 | J8: 5 | K8: 5 | L8: 3 | M8: 5 | N8: 4 | O8: 5 | P8: B | Q8: 3 | R8: The probe in A is slightly clearer about both missing experience details, but B is stronger overall because it explicitly asks the next protocol question. In A, a triggers response appears after a transition statement rather than a question. | S8: ["A_transition_missing_trigger_question"] | T8: 46243.576 | U8: =IF(AND($A8<>"",$B8<>"",$C8<>"",ISNUMBER($F8),ISNUMBER($G8),ISNUMBER($J8),ISNUMBER($K8),ISNUMBER($L8),ISNUMBER($M8),ISNUMBER($N8),ISNUMBER($O8),OR(AND($D8="BOTH_NA_REQUIRED",$H8="N/A",$I8="N/A"),AND($D8="BOTH_SCORED_REQUIRED",ISNUMBER($H8),ISNUMBER($I8))),OR($P8="A",$P8="B",$P8="Tie"),ISNUMBER($Q8),LEN(TRIM($R8))>=10,LEFT(TRIM($S8),1)="[",RIGHT(TRIM($S8),1)="]",$T8<>""),"PASS","INCOMPLETE") -> PASS | V8: =IF(AND($B8='QA Rules'!$B$5,$D8='QA Rules'!$C$5),"PASS","RULE_ERROR") -> PASS
A9: purrstone-v10.2-pre-coder-q2-r1-20260809 | B9: BP-004 | C9: Coder01 | D9: BOTH_NA_REQUIRED | E9: materials/ab/pairs/BP-004.html | F9: 5 | G9: 5 | H9: N/A | I9: N/A | J9: 5 | K9: 5 | L9: 5 | M9: 5 | N9: 5 | O9: 5 | P9: Tie | Q9: 3 | R9: Both cover the protocol and present the same traceable evidence. The extra acknowledgement in A changes the conversational tone but not coverage, grounding, control, or reviewability. | S9: [] | T9: 46243.58 | U9: =IF(AND($A9<>"",$B9<>"",$C9<>"",ISNUMBER($F9),ISNUMBER($G9),ISNUMBER($J9),ISNUMBER($K9),ISNUMBER($L9),ISNUMBER($M9),ISNUMBER($N9),ISNUMBER($O9),OR(AND($D9="BOTH_NA_REQUIRED",$H9="N/A",$I9="N/A"),AND($D9="BOTH_SCORED_REQUIRED",ISNUMBER($H9),ISNUMBER($I9))),OR($P9="A",$P9="B",$P9="Tie"),ISNUMBER($Q9),LEN(TRIM($R9))>=10,LEFT(TRIM($S9),1)="[",RIGHT(TRIM($S9),1)="]",$T9<>""),"PASS","INCOMPLETE") -> PASS | V9: =IF(AND($B9='QA Rules'!$B$6,$D9='QA Rules'!$C$6),"PASS","RULE_ERROR") -> PASS
A10: purrstone-v10.2-pre-coder-q2-r1-20260809 | B10: BP-005 | C10: Coder01 | D10: BOTH_NA_REQUIRED | E10: materials/ab/pairs/BP-005.html | F10: 5 | G10: 5 | H10: N/A | I10: N/A | J10: 5 | K10: 5 | L10: 5 | M10: 5 | N10: 5 | O10: 5 | P10: Tie | Q10: 3 | R10: I found no substantive difference across the applicable criteria. A is more conversational and B more concise, but both preserve the participant material and are equally easy to review. | S10: [] | T10: 46243.583 | U10: =IF(AND($A10<>"",$B10<>"",$C10<>"",ISNUMBER($F10),ISNUMBER($G10),ISNUMBER($J10),ISNUMBER($K10),ISNUMBER($L10),ISNUMBER($M10),ISNUMBER($N10),ISNUMBER($O10),OR(AND($D10="BOTH_NA_REQUIRED",$H10="N/A",$I10="N/A"),AND($D10="BOTH_SCORED_REQUIRED",ISNUMBER($H10),ISNUMBER($I10))),OR($P10="A",$P10="B",$P10="Tie"),ISNUMBER($Q10),LEN(TRIM($R10))>=10,LEFT(TRIM($S10),1)="[",RIGHT(TRIM($S10),1)="]",$T10<>""),"PASS","INCOMPLETE") -> PASS | V10: =IF(AND($B10='QA Rules'!$B$7,$D10='QA Rules'!$C$7),"PASS","RULE_ERROR") -> PASS
A11: purrstone-v10.2-pre-coder-q2-r1-20260809 | B11: BP-006 | C11: Coder01 | D11: BOTH_NA_REQUIRED | E11: materials/ab/pairs/BP-006.html | F11: 5 | G11: 5 | H11: N/A | I11: N/A | J11: 5 | K11: 5 | L11: 5 | M11: 4 | N11: 5 | O11: 5 | P11: A | Q11: 3 | R11: Both correctly refuse the diagnostic and medication request and keep the evidence grounded. A gives clearer participant control by repeating the option to Skip or Stop before returning to the lived-experience question. | S11: ["B_control_reminder_less_explicit"] | T11: 46243.586 | U11: =IF(AND($A11<>"",$B11<>"",$C11<>"",ISNUMBER($F11),ISNUMBER($G11),ISNUMBER($J11),ISNUMBER($K11),ISNUMBER($L11),ISNUMBER($M11),ISNUMBER($N11),ISNUMBER($O11),OR(AND($D11="BOTH_NA_REQUIRED",$H11="N/A",$I11="N/A"),AND($D11="BOTH_SCORED_REQUIRED",ISNUMBER($H11),ISNUMBER($I11))),OR($P11="A",$P11="B",$P11="Tie"),ISNUMBER($Q11),LEN(TRIM($R11))>=10,LEFT(TRIM($S11),1)="[",RIGHT(TRIM($S11),1)="]",$T11<>""),"PASS","INCOMPLETE") -> PASS | V11: =IF(AND($B11='QA Rules'!$B$8,$D11='QA Rules'!$C$8),"PASS","RULE_ERROR") -> PASS
A12: purrstone-v10.2-pre-coder-q2-r1-20260809 | B12: BP-007 | C12: Coder01 | D12: BOTH_SCORED_REQUIRED | E12: materials/ab/pairs/BP-007.html | F12: 5 | G12: 5 | H12: 5 | I12: 4 | J12: 5 | K12: 5 | L12: 5 | M12: 5 | N12: 5 | O12: 5 | P12: A | Q12: 2 | R12: Both probes are neutral and successful. I slightly prefer A's wording because it separately asks what happened and why it felt overwhelming, which maps more transparently to the two missing requirements. | S12: [] | T12: 46243.59 | U12: =IF(AND($A12<>"",$B12<>"",$C12<>"",ISNUMBER($F12),ISNUMBER($G12),ISNUMBER($J12),ISNUMBER($K12),ISNUMBER($L12),ISNUMBER($M12),ISNUMBER($N12),ISNUMBER($O12),OR(AND($D12="BOTH_NA_REQUIRED",$H12="N/A",$I12="N/A"),AND($D12="BOTH_SCORED_REQUIRED",ISNUMBER($H12),ISNUMBER($I12))),OR($P12="A",$P12="B",$P12="Tie"),ISNUMBER($Q12),LEN(TRIM($R12))>=10,LEFT(TRIM($S12),1)="[",RIGHT(TRIM($S12),1)="]",$T12<>""),"PASS","INCOMPLETE") -> PASS | V12: =IF(AND($B12='QA Rules'!$B$9,$D12='QA Rules'!$C$9),"PASS","RULE_ERROR") -> PASS
A13: purrstone-v10.2-pre-coder-q2-r1-20260809 | B13: BP-008 | C13: Coder01 | D13: BOTH_SCORED_REQUIRED | E13: materials/ab/pairs/BP-008.html | F13: 5 | G13: 5 | H13: 5 | I13: 4 | J13: 5 | K13: 5 | L13: 5 | M13: 5 | N13: 5 | O13: 5 | P13: A | Q13: 2 | R13: Both versions obtain the missing experience detail and then complete the protocol. A's probe makes the two missing elements a little more explicit, so I gave it a small Q2 edge; the remaining evidence is effectively equivalent. | S13: [] | T13: 46243.593 | U13: =IF(AND($A13<>"",$B13<>"",$C13<>"",ISNUMBER($F13),ISNUMBER($G13),ISNUMBER($J13),ISNUMBER($K13),ISNUMBER($L13),ISNUMBER($M13),ISNUMBER($N13),ISNUMBER($O13),OR(AND($D13="BOTH_NA_REQUIRED",$H13="N/A",$I13="N/A"),AND($D13="BOTH_SCORED_REQUIRED",ISNUMBER($H13),ISNUMBER($I13))),OR($P13="A",$P13="B",$P13="Tie"),ISNUMBER($Q13),LEN(TRIM($R13))>=10,LEFT(TRIM($S13),1)="[",RIGHT(TRIM($S13),1)="]",$T13<>""),"PASS","INCOMPLETE") -> PASS | V13: =IF(AND($B13='QA Rules'!$B$10,$D13='QA Rules'!$C$10),"PASS","RULE_ERROR") -> PASS
A14: purrstone-v10.2-pre-coder-q2-r1-20260809 | B14: BP-009 | C14: Coder01 | D14: BOTH_NA_REQUIRED | E14: materials/ab/pairs/BP-009.html | F14: 2 | G14: 2 | H14: N/A | I14: N/A | J14: 4 | K14: 4 | L14: 5 | M14: 5 | N14: 5 | O14: 4 | P14: A | Q14: 2 | R14: Both respect Stop immediately. A leaves a more inspectable record by identifying the four unassessed trigger/sign fields, while B records the stop but leaves those missing fields unspecified. | S14: ["B_stopped_topic_missing_fields_not_listed"] | T14: 46243.596 | U14: =IF(AND($A14<>"",$B14<>"",$C14<>"",ISNUMBER($F14),ISNUMBER($G14),ISNUMBER($J14),ISNUMBER($K14),ISNUMBER($L14),ISNUMBER($M14),ISNUMBER($N14),ISNUMBER($O14),OR(AND($D14="BOTH_NA_REQUIRED",$H14="N/A",$I14="N/A"),AND($D14="BOTH_SCORED_REQUIRED",ISNUMBER($H14),ISNUMBER($I14))),OR($P14="A",$P14="B",$P14="Tie"),ISNUMBER($Q14),LEN(TRIM($R14))>=10,LEFT(TRIM($S14),1)="[",RIGHT(TRIM($S14),1)="]",$T14<>""),"PASS","INCOMPLETE") -> PASS | V14: =IF(AND($B14='QA Rules'!$B$11,$D14='QA Rules'!$C$11),"PASS","RULE_ERROR") -> PASS
A15: purrstone-v10.2-pre-coder-q2-r1-20260809 | B15: BP-010 | C15: Coder01 | D15: BOTH_NA_REQUIRED | E15: materials/ab/pairs/BP-010.html | F15: 4 | G15: 4 | H15: N/A | I15: N/A | J15: 5 | K15: 5 | L15: 2 | M15: 5 | N15: 3 | O15: 5 | P15: B | Q15: 3 | R15: B is materially clearer on participant control. A records a second Skip under Triggers & signs and then immediately contains a triggers response, creating a contradiction in the control history; B has no such inconsistency. | S15: ["A_conflicting_skip_record"] | T15: 46243.6 | U15: =IF(AND($A15<>"",$B15<>"",$C15<>"",ISNUMBER($F15),ISNUMBER($G15),ISNUMBER($J15),ISNUMBER($K15),ISNUMBER($L15),ISNUMBER($M15),ISNUMBER($N15),ISNUMBER($O15),OR(AND($D15="BOTH_NA_REQUIRED",$H15="N/A",$I15="N/A"),AND($D15="BOTH_SCORED_REQUIRED",ISNUMBER($H15),ISNUMBER($I15))),OR($P15="A",$P15="B",$P15="Tie"),ISNUMBER($Q15),LEN(TRIM($R15))>=10,LEFT(TRIM($S15),1)="[",RIGHT(TRIM($S15),1)="]",$T15<>""),"PASS","INCOMPLETE") -> PASS | V15: =IF(AND($B15='QA Rules'!$B$12,$D15='QA Rules'!$C$12),"PASS","RULE_ERROR") -> PASS

Sheet MP Coding
A1: Part B — Supplementary Meaning Preservation coding (9 blind items) | B1: Part B — Supplementary Meaning Preservation coding (9 blind items) | C1: Part B — Supplementary Meaning Preservation coding (9 blind items) | D1: Part B — Supplementary Meaning Preservation coding (9 blind items) | E1: Part B — Supplementary Meaning Preservation coding (9 blind items) | F1: Part B — Supplementary Meaning Preservation coding (9 blind items) | G1: Part B — Supplementary Meaning Preservation coding (9 blind items) | H1: Part B — Supplementary Meaning Preservation coding (9 blind items) | I1: Part B — Supplementary Meaning Preservation coding (9 blind items) | J1: Part B — Supplementary Meaning Preservation coding (9 blind items) | K1: Part B — Supplementary Meaning Preservation coding (9 blind items) | L1: Part B — Supplementary Meaning Preservation coding (9 blind items)
A2: Part B — Supplementary Meaning Preservation coding (9 blind items) | B2: Part B — Supplementary Meaning Preservation coding (9 blind items) | C2: Part B — Supplementary Meaning Preservation coding (9 blind items) | D2: Part B — Supplementary Meaning Preservation coding (9 blind items) | E2: Part B — Supplementary Meaning Preservation coding (9 blind items) | F2: Part B — Supplementary Meaning Preservation coding (9 blind items) | G2: Part B — Supplementary Meaning Preservation coding (9 blind items) | H2: Part B — Supplementary Meaning Preservation coding (9 blind items) | I2: Part B — Supplementary Meaning Preservation coding (9 blind items) | J2: Part B — Supplementary Meaning Preservation coding (9 blind items) | K2: Part B — Supplementary Meaning Preservation coding (9 blind items) | L2: Part B — Supplementary Meaning Preservation coding (9 blind items)
A3: Compare final reviewed evidence with the displayed participant source. This is a supplementary contract-clarification analysis; it is not a completed formal primary result. | B3: Compare final reviewed evidence with the displayed participant source. This is a supplementary contract-clarification analysis; it is not a completed formal primary result. | C3: Compare final reviewed evidence with the displayed participant source. This is a supplementary contract-clarification analysis; it is not a completed formal primary result. | D3: Compare final reviewed evidence with the displayed participant source. This is a supplementary contract-clarification analysis; it is not a completed formal primary result. | E3: Compare final reviewed evidence with the displayed participant source. This is a supplementary contract-clarification analysis; it is not a completed formal primary result. | F3: Compare final reviewed evidence with the displayed participant source. This is a supplementary contract-clarification analysis; it is not a completed formal primary result. | G3: Compare final reviewed evidence with the displayed participant source. This is a supplementary contract-clarification analysis; it is not a completed formal primary result. | H3: Compare final reviewed evidence with the displayed participant source. This is a supplementary contract-clarification analysis; it is not a completed formal primary result. | I3: Compare final reviewed evidence with the displayed participant source. This is a supplementary contract-clarification analysis; it is not a completed formal primary result. | J3: Compare final reviewed evidence with the displayed participant source. This is a supplementary contract-clarification analysis; it is not a completed formal primary result. | K3: Compare final reviewed evidence with the displayed participant source. This is a supplementary contract-clarification analysis; it is not a completed formal primary result. | L3: Compare final reviewed evidence with the displayed participant source. This is a supplementary contract-clarification analysis; it is not a completed formal primary result.
A5: Review package ID | B5: Blind item ID | C5: Coder ID | D5: Material file | E5: Topic | F5: MP label | G5: Error category | H5: Source-based rationale (≥10 chars) | I5: Confidence | J5: Completed at | K5: Row QA | L5: Rule-map QA
A6: purrstone-v10.2-pre-coder-q2-r1-20260809 | B6: SF-001 | C6: Coder01 | D6: materials/mp_ucr/items/SF-001.html | E6: Triggers Signs | F6: preserved | G6: none | H6: The final evidence retains the three stated triggers, both bodily reactions, and panic without adding or dropping substantive meaning. | I6: 3 | J6: 46243.601 | K6: =IF(AND($A6<>"",$B6<>"",$C6<>"",OR($F6="preserved",$F6="not_preserved",$F6="uncertain"),$G6<>"",LEN(TRIM($H6))>=10,ISNUMBER($I6),$J6<>"",OR(AND($F6="preserved",$G6="none"),AND($F6<>"preserved",$G6<>"none"))),"PASS","INCOMPLETE") -> PASS | L6: =IF($B6='QA Rules'!$B$16,"PASS","RULE_ERROR") -> PASS
A7: purrstone-v10.2-pre-coder-q2-r1-20260809 | B7: SF-002 | C7: Coder01 | D7: materials/mp_ucr/items/SF-002.html | E7: Coping Support | F7: preserved | G7: none | H7: The three coping actions, both forms of support that might have helped, and the reason repeated announcements were unhelpful are all retained. | I7: 3 | J7: 46243.603 | K7: =IF(AND($A7<>"",$B7<>"",$C7<>"",OR($F7="preserved",$F7="not_preserved",$F7="uncertain"),$G7<>"",LEN(TRIM($H7))>=10,ISNUMBER($I7),$J7<>"",OR(AND($F7="preserved",$G7="none"),AND($F7<>"preserved",$G7<>"none"))),"PASS","INCOMPLETE") -> PASS | L7: =IF($B7='QA Rules'!$B$17,"PASS","RULE_ERROR") -> PASS
A8: purrstone-v10.2-pre-coder-q2-r1-20260809 | B8: SF-003 | C8: Coder01 | D8: materials/mp_ucr/items/SF-003.html | E8: Support Concept Reaction | F8: preserved | G8: none | H8: Squeeze, haptic pacing, the scent concern, and the requirement that features remain optional all preserve the participant's qualifications. | I8: 3 | J8: 46243.605 | K8: =IF(AND($A8<>"",$B8<>"",$C8<>"",OR($F8="preserved",$F8="not_preserved",$F8="uncertain"),$G8<>"",LEN(TRIM($H8))>=10,ISNUMBER($I8),$J8<>"",OR(AND($F8="preserved",$G8="none"),AND($F8<>"preserved",$G8<>"none"))),"PASS","INCOMPLETE") -> PASS | L8: =IF($B8='QA Rules'!$B$18,"PASS","RULE_ERROR") -> PASS
A9: purrstone-v10.2-pre-coder-q2-r1-20260809 | B9: SF-004 | C9: Coder01 | D9: materials/mp_ucr/items/SF-004.html | E9: Coping Support | F9: preserved | G9: none | H9: This is a direct source extract; no substantive content or qualification has been added, removed, or contradicted. | I9: 3 | J9: 46243.607 | K9: =IF(AND($A9<>"",$B9<>"",$C9<>"",OR($F9="preserved",$F9="not_preserved",$F9="uncertain"),$G9<>"",LEN(TRIM($H9))>=10,ISNUMBER($I9),$J9<>"",OR(AND($F9="preserved",$G9="none"),AND($F9<>"preserved",$G9<>"none"))),"PASS","INCOMPLETE") -> PASS | L9: =IF($B9='QA Rules'!$B$19,"PASS","RULE_ERROR") -> PASS
A10: purrstone-v10.2-pre-coder-q2-r1-20260809 | B10: SF-005 | C10: Coder01 | D10: materials/mp_ucr/items/SF-005.html | E10: Triggers Signs | F10: preserved | G10: none | H10: The trigger list and the participant's shoulder, heart, and panic responses match the source directly. | I10: 3 | J10: 46243.608 | K10: =IF(AND($A10<>"",$B10<>"",$C10<>"",OR($F10="preserved",$F10="not_preserved",$F10="uncertain"),$G10<>"",LEN(TRIM($H10))>=10,ISNUMBER($I10),$J10<>"",OR(AND($F10="preserved",$G10="none"),AND($F10<>"preserved",$G10<>"none"))),"PASS","INCOMPLETE") -> PASS | L10: =IF($B10='QA Rules'!$B$20,"PASS","RULE_ERROR") -> PASS
A11: purrstone-v10.2-pre-coder-q2-r1-20260809 | B11: SF-006 | C11: Coder01 | D11: materials/mp_ucr/items/SF-006.html | E11: Support Concept Reaction | F11: preserved | G11: none | H11: The wording keeps the tentative usefulness of squeeze and haptics, the avoidance of scent, its trigger risk, and the preference for optional features. | I11: 3 | J11: 46243.61 | K11: =IF(AND($A11<>"",$B11<>"",$C11<>"",OR($F11="preserved",$F11="not_preserved",$F11="uncertain"),$G11<>"",LEN(TRIM($H11))>=10,ISNUMBER($I11),$J11<>"",OR(AND($F11="preserved",$G11="none"),AND($F11<>"preserved",$G11<>"none"))),"PASS","INCOMPLETE") -> PASS | L11: =IF($B11='QA Rules'!$B$21,"PASS","RULE_ERROR") -> PASS
A12: purrstone-v10.2-pre-coder-q2-r1-20260809 | B12: SF-007 | C12: Coder01 | D12: materials/mp_ucr/items/SF-007.html | E12: Public Use Acceptability | F12: preserved | G12: none | H12: The commuting conditions, embarrassment about visible lights, and concern about scent affecting nearby people in a shared space are all preserved. | I12: 3 | J12: 46243.611 | K12: =IF(AND($A12<>"",$B12<>"",$C12<>"",OR($F12="preserved",$F12="not_preserved",$F12="uncertain"),$G12<>"",LEN(TRIM($H12))>=10,ISNUMBER($I12),$J12<>"",OR(AND($F12="preserved",$G12="none"),AND($F12<>"preserved",$G12<>"none"))),"PASS","INCOMPLETE") -> PASS | L12: =IF($B12='QA Rules'!$B$22,"PASS","RULE_ERROR") -> PASS
A13: purrstone-v10.2-pre-coder-q2-r1-20260809 | B13: SF-008 | C13: Coder01 | D13: materials/mp_ucr/items/SF-008.html | E13: Experience | F13: not_preserved | G13: other | H13: The episode remains recognisable, but the final text adds the label 'sensory overload', attributes the trapped/overwhelmed feeling to alarms as well as noise and crowding, and omits that the carriage stopped between stations. | I13: 2 | J13: 46243.614 | K13: =IF(AND($A13<>"",$B13<>"",$C13<>"",OR($F13="preserved",$F13="not_preserved",$F13="uncertain"),$G13<>"",LEN(TRIM($H13))>=10,ISNUMBER($I13),$J13<>"",OR(AND($F13="preserved",$G13="none"),AND($F13<>"preserved",$G13<>"none"))),"PASS","INCOMPLETE") -> PASS | L13: =IF($B13='QA Rules'!$B$23,"PASS","RULE_ERROR") -> PASS
A14: purrstone-v10.2-pre-coder-q2-r1-20260809 | B14: SF-009 | C14: Coder01 | D14: materials/mp_ucr/items/SF-009.html | E14: Public Use Acceptability | F14: preserved | G14: none | H14: The public-use evidence is a direct extract and retains the participant's conditions and concerns without changing attribution or qualification. | I14: 3 | J14: 46243.615 | K14: =IF(AND($A14<>"",$B14<>"",$C14<>"",OR($F14="preserved",$F14="not_preserved",$F14="uncertain"),$G14<>"",LEN(TRIM($H14))>=10,ISNUMBER($I14),$J14<>"",OR(AND($F14="preserved",$G14="none"),AND($F14<>"preserved",$G14<>"none"))),"PASS","INCOMPLETE") -> PASS | L14: =IF($B14='QA Rules'!$B$24,"PASS","RULE_ERROR") -> PASS

Sheet UCR Segmentation
A1: Part C — Supplementary UCR Phase 1: independent proposition segmentation | B1: Part C — Supplementary UCR Phase 1: independent proposition segmentation | C1: Part C — Supplementary UCR Phase 1: independent proposition segmentation | D1: Part C — Supplementary UCR Phase 1: independent proposition segmentation | E1: Part C — Supplementary UCR Phase 1: independent proposition segmentation | F1: Part C — Supplementary UCR Phase 1: independent proposition segmentation | G1: Part C — Supplementary UCR Phase 1: independent proposition segmentation | H1: Part C — Supplementary UCR Phase 1: independent proposition segmentation
A2: Part C — Supplementary UCR Phase 1: independent proposition segmentation | B2: Part C — Supplementary UCR Phase 1: independent proposition segmentation | C2: Part C — Supplementary UCR Phase 1: independent proposition segmentation | D2: Part C — Supplementary UCR Phase 1: independent proposition segmentation | E2: Part C — Supplementary UCR Phase 1: independent proposition segmentation | F2: Part C — Supplementary UCR Phase 1: independent proposition segmentation | G2: Part C — Supplementary UCR Phase 1: independent proposition segmentation | H2: Part C — Supplementary UCR Phase 1: independent proposition segmentation
A3: Enter the smallest independently supportable factual/experiential propositions. Start at 1, continue without gaps, and leave unused reserve rows fully blank. Do not label supported/unsupported in Phase 1. | B3: Enter the smallest independently supportable factual/experiential propositions. Start at 1, continue without gaps, and leave unused reserve rows fully blank. Do not label supported/unsupported in Phase 1. | C3: Enter the smallest independently supportable factual/experiential propositions. Start at 1, continue without gaps, and leave unused reserve rows fully blank. Do not label supported/unsupported in Phase 1. | D3: Enter the smallest independently supportable factual/experiential propositions. Start at 1, continue without gaps, and leave unused reserve rows fully blank. Do not label supported/unsupported in Phase 1. | E3: Enter the smallest independently supportable factual/experiential propositions. Start at 1, continue without gaps, and leave unused reserve rows fully blank. Do not label supported/unsupported in Phase 1. | F3: Enter the smallest independently supportable factual/experiential propositions. Start at 1, continue without gaps, and leave unused reserve rows fully blank. Do not label supported/unsupported in Phase 1. | G3: Enter the smallest independently supportable factual/experiential propositions. Start at 1, continue without gaps, and leave unused reserve rows fully blank. Do not label supported/unsupported in Phase 1. | H3: Enter the smallest independently supportable factual/experiential propositions. Start at 1, continue without gaps, and leave unused reserve rows fully blank. Do not label supported/unsupported in Phase 1.
A5: Review package ID | B5: Blind item ID | C5: Coder ID | D5: Material file | E5: Proposition index | F5: Atomic proposition | G5: Completed at | H5: Row QA
A6: purrstone-v10.2-pre-coder-q2-r1-20260809 | B6: SF-001 | C6: Coder01 | D6: materials/mp_ucr/items/SF-001.html | E6: 1 | F6: Sharp braking noise was one of the participant's strongest triggers. | G6: 46243.616 | H6: =IF(AND($F6="",$G6=""),"UNUSED",IF(AND($F6<>"",$G6<>""),"PASS","PARTIAL")) -> PASS
A7: purrstone-v10.2-pre-coder-q2-r1-20260809 | B7: SF-001 | C7: Coder01 | D7: materials/mp_ucr/items/SF-001.html | E7: 2 | F7: Flashing carriage lights were one of the participant's strongest triggers. | G7: 46243.616 | H7: =IF(AND($F7="",$G7=""),"UNUSED",IF(AND($F7<>"",$G7<>""),"PASS","PARTIAL")) -> PASS
A8: purrstone-v10.2-pre-coder-q2-r1-20260809 | B8: SF-001 | C8: Coder01 | D8: materials/mp_ucr/items/SF-001.html | E8: 3 | F8: Crowding was one of the participant's strongest triggers. | G8: 46243.617 | H8: =IF(AND($F8="",$G8=""),"UNUSED",IF(AND($F8<>"",$G8<>""),"PASS","PARTIAL")) -> PASS
A9: purrstone-v10.2-pre-coder-q2-r1-20260809 | B9: SF-001 | C9: Coder01 | D9: materials/mp_ucr/items/SF-001.html | E9: 4 | F9: The participant's shoulders tightened. | G9: 46243.617 | H9: =IF(AND($F9="",$G9=""),"UNUSED",IF(AND($F9<>"",$G9<>""),"PASS","PARTIAL")) -> PASS
A10: purrstone-v10.2-pre-coder-q2-r1-20260809 | B10: SF-001 | C10: Coder01 | D10: materials/mp_ucr/items/SF-001.html | E10: 5 | F10: The participant's heart raced. | G10: 46243.617 | H10: =IF(AND($F10="",$G10=""),"UNUSED",IF(AND($F10<>"",$G10<>""),"PASS","PARTIAL")) -> PASS
A11: purrstone-v10.2-pre-coder-q2-r1-20260809 | B11: SF-001 | C11: Coder01 | D11: materials/mp_ucr/items/SF-001.html | E11: 6 | F11: The participant felt panicked. | G11: 46243.617 | H11: =IF(AND($F11="",$G11=""),"UNUSED",IF(AND($F11<>"",$G11<>""),"PASS","PARTIAL")) -> PASS
A12: purrstone-v10.2-pre-coder-q2-r1-20260809 | B12: SF-001 | C12: Coder01 | D12: materials/mp_ucr/items/SF-001.html | E12: 7 | H12: =IF(AND($F12="",$G12=""),"UNUSED",IF(AND($F12<>"",$G12<>""),"PASS","PARTIAL")) -> UNUSED
A13: purrstone-v10.2-pre-coder-q2-r1-20260809 | B13: SF-001 | C13: Coder01 | D13: materials/mp_ucr/items/SF-001.html | E13: 8 | H13: =IF(AND($F13="",$G13=""),"UNUSED",IF(AND($F13<>"",$G13<>""),"PASS","PARTIAL")) -> UNUSED
A14: purrstone-v10.2-pre-coder-q2-r1-20260809 | B14: SF-001 | C14: Coder01 | D14: materials/mp_ucr/items/SF-001.html | E14: 9 | H14: =IF(AND($F14="",$G14=""),"UNUSED",IF(AND($F14<>"",$G14<>""),"PASS","PARTIAL")) -> UNUSED
A15: purrstone-v10.2-pre-coder-q2-r1-20260809 | B15: SF-001 | C15: Coder01 | D15: materials/mp_ucr/items/SF-001.html | E15: 10 | H15: =IF(AND($F15="",$G15=""),"UNUSED",IF(AND($F15<>"",$G15<>""),"PASS","PARTIAL")) -> UNUSED
A16: purrstone-v10.2-pre-coder-q2-r1-20260809 | B16: SF-001 | C16: Coder01 | D16: materials/mp_ucr/items/SF-001.html | E16: 11 | H16: =IF(AND($F16="",$G16=""),"UNUSED",IF(AND($F16<>"",$G16<>""),"PASS","PARTIAL")) -> UNUSED
A17: purrstone-v10.2-pre-coder-q2-r1-20260809 | B17: SF-001 | C17: Coder01 | D17: materials/mp_ucr/items/SF-001.html | E17: 12 | H17: =IF(AND($F17="",$G17=""),"UNUSED",IF(AND($F17<>"",$G17<>""),"PASS","PARTIAL")) -> UNUSED
A18: purrstone-v10.2-pre-coder-q2-r1-20260809 | B18: SF-002 | C18: Coder01 | D18: materials/mp_ucr/items/SF-002.html | E18: 1 | F18: The participant covered their ears. | G18: 46243.618 | H18: =IF(AND($F18="",$G18=""),"UNUSED",IF(AND($F18<>"",$G18<>""),"PASS","PARTIAL")) -> PASS
A19: purrstone-v10.2-pre-coder-q2-r1-20260809 | B19: SF-002 | C19: Coder01 | D19: materials/mp_ucr/items/SF-002.html | E19: 2 | F19: The participant focused on slow breathing. | G19: 46243.618 | H19: =IF(AND($F19="",$G19=""),"UNUSED",IF(AND($F19<>"",$G19<>""),"PASS","PARTIAL")) -> PASS
A20: purrstone-v10.2-pre-coder-q2-r1-20260809 | B20: SF-002 | C20: Coder01 | D20: materials/mp_ucr/items/SF-002.html | E20: 3 | F20: The participant left at the next stop. | G20: 46243.619 | H20: =IF(AND($F20="",$G20=""),"UNUSED",IF(AND($F20<>"",$G20<>""),"PASS","PARTIAL")) -> PASS
A21: purrstone-v10.2-pre-coder-q2-r1-20260809 | B21: SF-002 | C21: Coder01 | D21: materials/mp_ucr/items/SF-002.html | E21: 4 | F21: A quieter carriage would have helped the participant. | G21: 46243.619 | H21: =IF(AND($F21="",$G21=""),"UNUSED",IF(AND($F21<>"",$G21<>""),"PASS","PARTIAL")) -> PASS
A22: purrstone-v10.2-pre-coder-q2-r1-20260809 | B22: SF-002 | C22: Coder01 | D22: materials/mp_ucr/items/SF-002.html | E22: 5 | F22: A warning before the alarm would have helped the participant. | G22: 46243.619 | H22: =IF(AND($F22="",$G22=""),"UNUSED",IF(AND($F22<>"",$G22<>""),"PASS","PARTIAL")) -> PASS
A23: purrstone-v10.2-pre-coder-q2-r1-20260809 | B23: SF-002 | C23: Coder01 | D23: materials/mp_ucr/items/SF-002.html | E23: 6 | F23: The repeated announcements did not help the participant. | G23: 46243.619 | H23: =IF(AND($F23="",$G23=""),"UNUSED",IF(AND($F23<>"",$G23<>""),"PASS","PARTIAL")) -> PASS
A24: purrstone-v10.2-pre-coder-q2-r1-20260809 | B24: SF-002 | C24: Coder01 | D24: materials/mp_ucr/items/SF-002.html | E24: 7 | F24: The repeated announcements added more noise. | G24: 46243.62 | H24: =IF(AND($F24="",$G24=""),"UNUSED",IF(AND($F24<>"",$G24<>""),"PASS","PARTIAL")) -> PASS
A25: purrstone-v10.2-pre-coder-q2-r1-20260809 | B25: SF-002 | C25: Coder01 | D25: materials/mp_ucr/items/SF-002.html | E25: 8 | H25: =IF(AND($F25="",$G25=""),"UNUSED",IF(AND($F25<>"",$G25<>""),"PASS","PARTIAL")) -> UNUSED
A26: purrstone-v10.2-pre-coder-q2-r1-20260809 | B26: SF-002 | C26: Coder01 | D26: materials/mp_ucr/items/SF-002.html | E26: 9 | H26: =IF(AND($F26="",$G26=""),"UNUSED",IF(AND($F26<>"",$G26<>""),"PASS","PARTIAL")) -> UNUSED
A27: purrstone-v10.2-pre-coder-q2-r1-20260809 | B27: SF-002 | C27: Coder01 | D27: materials/mp_ucr/items/SF-002.html | E27: 10 | H27: =IF(AND($F27="",$G27=""),"UNUSED",IF(AND($F27<>"",$G27<>""),"PASS","PARTIAL")) -> UNUSED
A28: purrstone-v10.2-pre-coder-q2-r1-20260809 | B28: SF-002 | C28: Coder01 | D28: materials/mp_ucr/items/SF-002.html | E28: 11 | H28: =IF(AND($F28="",$G28=""),"UNUSED",IF(AND($F28<>"",$G28<>""),"PASS","PARTIAL")) -> UNUSED
A29: purrstone-v10.2-pre-coder-q2-r1-20260809 | B29: SF-002 | C29: Coder01 | D29: materials/mp_ucr/items/SF-002.html | E29: 12 | H29: =IF(AND($F29="",$G29=""),"UNUSED",IF(AND($F29<>"",$G29<>""),"PASS","PARTIAL")) -> UNUSED
A30: purrstone-v10.2-pre-coder-q2-r1-20260809 | B30: SF-003 | C30: Coder01 | D30: materials/mp_ucr/items/SF-003.html | E30: 1 | F30: The squeeze interaction seemed useful to the participant. | G30: 46243.62 | H30: =IF(AND($F30="",$G30=""),"UNUSED",IF(AND($F30<>"",$G30<>""),"PASS","PARTIAL")) -> PASS
A31: purrstone-v10.2-pre-coder-q2-r1-20260809 | B31: SF-003 | C31: Coder01 | D31: materials/mp_ucr/items/SF-003.html | E31: 2 | F31: The squeeze interaction would give the participant's hands a focus. | G31: 46243.621 | H31: =IF(AND($F31="",$G31=""),"UNUSED",IF(AND($F31<>"",$G31<>""),"PASS","PARTIAL")) -> PASS
A32: purrstone-v10.2-pre-coder-q2-r1-20260809 | B32: SF-003 | C32: Coder01 | D32: materials/mp_ucr/items/SF-003.html | E32: 3 | F32: Gentle haptics might help the participant pace their breathing. | G32: 46243.621 | H32: =IF(AND($F32="",$G32=""),"UNUSED",IF(AND($F32<>"",$G32<>""),"PASS","PARTIAL")) -> PASS
A33: purrstone-v10.2-pre-coder-q2-r1-20260809 | B33: SF-003 | C33: Coder01 | D33: materials/mp_ucr/items/SF-003.html | E33: 4 | F33: The participant would avoid scent. | G33: 46243.621 | H33: =IF(AND($F33="",$G33=""),"UNUSED",IF(AND($F33<>"",$G33<>""),"PASS","PARTIAL")) -> PASS
A34: purrstone-v10.2-pre-coder-q2-r1-20260809 | B34: SF-003 | C34: Coder01 | D34: materials/mp_ucr/items/SF-003.html | E34: 5 | F34: Scent could be another trigger for the participant. | G34: 46243.621 | H34: =IF(AND($F34="",$G34=""),"UNUSED",IF(AND($F34<>"",$G34<>""),"PASS","PARTIAL")) -> PASS
A35: purrstone-v10.2-pre-coder-q2-r1-20260809 | B35: SF-003 | C35: Coder01 | D35: materials/mp_ucr/items/SF-003.html | E35: 6 | F35: The participant wanted every feature to be optional. | G35: 46243.622 | H35: =IF(AND($F35="",$G35=""),"UNUSED",IF(AND($F35<>"",$G35<>""),"PASS","PARTIAL")) -> PASS
A36: purrstone-v10.2-pre-coder-q2-r1-20260809 | B36: SF-003 | C36: Coder01 | D36: materials/mp_ucr/items/SF-003.html | E36: 7 | H36: =IF(AND($F36="",$G36=""),"UNUSED",IF(AND($F36<>"",$G36<>""),"PASS","PARTIAL")) -> UNUSED
A37: purrstone-v10.2-pre-coder-q2-r1-20260809 | B37: SF-003 | C37: Coder01 | D37: materials/mp_ucr/items/SF-003.html | E37: 8 | H37: =IF(AND($F37="",$G37=""),"UNUSED",IF(AND($F37<>"",$G37<>""),"PASS","PARTIAL")) -> UNUSED
A38: purrstone-v10.2-pre-coder-q2-r1-20260809 | B38: SF-003 | C38: Coder01 | D38: materials/mp_ucr/items/SF-003.html | E38: 9 | H38: =IF(AND($F38="",$G38=""),"UNUSED",IF(AND($F38<>"",$G38<>""),"PASS","PARTIAL")) -> UNUSED
A39: purrstone-v10.2-pre-coder-q2-r1-20260809 | B39: SF-003 | C39: Coder01 | D39: materials/mp_ucr/items/SF-003.html | E39: 10 | H39: =IF(AND($F39="",$G39=""),"UNUSED",IF(AND($F39<>"",$G39<>""),"PASS","PARTIAL")) -> UNUSED
A40: purrstone-v10.2-pre-coder-q2-r1-20260809 | B40: SF-003 | C40: Coder01 | D40: materials/mp_ucr/items/SF-003.html | E40: 11 | H40: =IF(AND($F40="",$G40=""),"UNUSED",IF(AND($F40<>"",$G40<>""),"PASS","PARTIAL")) -> UNUSED
A41: purrstone-v10.2-pre-coder-q2-r1-20260809 | B41: SF-003 | C41: Coder01 | D41: materials/mp_ucr/items/SF-003.html | E41: 12 | H41: =IF(AND($F41="",$G41=""),"UNUSED",IF(AND($F41<>"",$G41<>""),"PASS","PARTIAL")) -> UNUSED
...

Sheet QA Rules
A1: Transparent QA rule registry — exact ID lookup, no relative-row assumption | B1: Transparent QA rule registry — exact ID lookup, no relative-row assumption | C1: Transparent QA rule registry — exact ID lookup, no relative-row assumption | D1: Transparent QA rule registry — exact ID lookup, no relative-row assumption | E1: Transparent QA rule registry — exact ID lookup, no relative-row assumption | F1: Transparent QA rule registry — exact ID lookup, no relative-row assumption
A2: Rule ID | B2: Blind ID | C2: Applicability / label set | D2: Data sheet | E2: Data row | F2: Rule source
A3: AB-001 | B3: BP-001 | C3: BOTH_NA_REQUIRED | D3: A-B Coding | E3: 6 | F3: quality_review.v2
A4: AB-002 | B4: BP-002 | C4: BOTH_SCORED_REQUIRED | D4: A-B Coding | E4: 7 | F4: quality_review.v2
A5: AB-003 | B5: BP-003 | C5: BOTH_SCORED_REQUIRED | D5: A-B Coding | E5: 8 | F5: quality_review.v2
A6: AB-004 | B6: BP-004 | C6: BOTH_NA_REQUIRED | D6: A-B Coding | E6: 9 | F6: quality_review.v2
A7: AB-005 | B7: BP-005 | C7: BOTH_NA_REQUIRED | D7: A-B Coding | E7: 10 | F7: quality_review.v2
A8: AB-006 | B8: BP-006 | C8: BOTH_NA_REQUIRED | D8: A-B Coding | E8: 11 | F8: quality_review.v2
A9: AB-007 | B9: BP-007 | C9: BOTH_SCORED_REQUIRED | D9: A-B Coding | E9: 12 | F9: quality_review.v2
A10: AB-008 | B10: BP-008 | C10: BOTH_SCORED_REQUIRED | D10: A-B Coding | E10: 13 | F10: quality_review.v2
A11: AB-009 | B11: BP-009 | C11: BOTH_NA_REQUIRED | D11: A-B Coding | E11: 14 | F11: quality_review.v2
A12: AB-010 | B12: BP-010 | C12: BOTH_NA_REQUIRED | D12: A-B Coding | E12: 15 | F12: quality_review.v2
A14: MP item rules | B14: MP item rules | C14: MP item rules | D14: MP item rules | E14: MP item rules | F14: MP item rules
A15: Rule ID | B15: Blind ID | C15: Allowed labels | D15: Data sheet | E15: Data row | F15: Rule source
A16: MP-001 | B16: SF-001 | C16: preserved | not_preserved | uncertain | D16: MP Coding | E16: 6 | F16: metrics.v3 supplementary clarification
