Workbook

Sheet Start Here
A1: PurrStone v10.2 — Phase 1 UCR Reconciliation
A4: Use this workbook only after both independent Phase 1 returns are frozen. Both coders may now discuss proposition boundaries, but must remain blind to condition, pair, scenario and run identities.
A6: Reconciliation build ID | B6: purrstone-v10.2-ucr-reconciliation-r1-20260810
A7: Material-set SHA-256 | B7: 67afa8c732e79b430031f6e40678989fd5efe1fd65c0fb26d6527be54b050901
A8: Coder01 return SHA-256 | B8: 675c4f4fc1a4d178acfb95c9b07bbf128c9c956e1bd9414c148dbfa5005f1cc7
A9: Coder02 return SHA-256 | B9: 679e6513e5e7baab98eacbb2569980c4a2631ad854de9db114483dd19d33d10c
A10: Independent returns | B10: Frozen; do not edit or overwrite
A11: Current stage | B11: Joint inventory reconciliation before Phase 2
A14: 1 — What has already passed | B14: Both files contain the same nine blind materials, complete MP and UCR entries, complete declarations and formula QA = PASS. MP agreement is 9/9 preserved. Because every MP label is identical, Cohen's kappa is not estimable; report raw agreement instead.
A15: 2 — What needs reconciliation | B15: Coder01 produced 49 propositions and Coder02 produced 46. Seven items have equivalent proposition boundaries. MD-004 and MD-005 contain genuine split/merge differences around causal relations.
A16: 3 — How to decide | B16: Retain the smallest independently supportable proposition without deleting a stated relationship. A causal statement may remain one atomic relational proposition when splitting it would remove the 'because' relation.
A17: 4 — What to complete | B17: Review Boundary Review, edit the yellow cells in Final Inventory if needed, confirm each item in Item Confirmation, then complete Joint Sign-off. Do not enter supported/unsupported labels here.
A18: 5 — Identity | B18: Use real names/signatures in the private original, or use coded IDs only if the researcher retains a private identity key. The public evidence package may contain a redacted copy.

Sheet Return Audit
A1: Independent Phase 1 Return Audit
A4: This sheet records pre-reconciliation results. Consensus must not be presented as independent agreement.
A6: Check | B6: Coder01 | C6: Coder02 | D6: Combined result | E6: Status | F6: Interpretation
A7: Material set SHA-256 | B7: 67afa8c732e79b430031f6e40678989fd5efe1fd65c0fb26d6527be54b050901 | C7: 67afa8c732e79b430031f6e40678989fd5efe1fd65c0fb26d6527be54b050901 | D7: Same | E7: PASS | F7: Both coders received the same nine blind bundles.
A8: Workbook formula QA | B8: PASS | C8: PASS | D8: Both PASS | E8: PASS | F8: All required Phase 1 fields and item checks are complete.
A9: Independent declaration | B9: Yes | C9: Yes | D9: Both Yes | E9: PASS | F9: Both declared independent work, no unblinding and no automated assistance.
A10: Coding duration | B10: 01:10:51 | C10: 01:08:38 | D10: Plausible | E10: PASS | F10: Coder01: 13:18:44–14:29:35; Coder02: 14:34:17–15:42:55 (+08:00).
A11: MP completed items | B11: 9 | C11: 9 | D11: 18/18 complete | E11: PASS | F11: All nine items were independently assessed by both coders.
A12: MP preserved | B12: 9 | C12: 9 | D12: 9/9 raw agreement | E12: PASS | F12: All materials are verbatim-equivalent draft/source bundles.
A13: MP confidence | B13: 3 for 9/9 | C13: 3 for 9/9 | D13: Same | E13: PASS | F13: High confidence is coherent with exact draft/source correspondence.
A14: MP Cohen's κ | B14: N/A | C14: N/A | D14: Not estimable | E14: INFO | F14: All judgments occupy one category; do not report κ = 1.
A15: UCR propositions | B15: 49 | C15: 46 | D15: 95 independent entries | E15: PASS | F15: Counts differ naturally; neither return was edited.
A16: Equivalent-boundary items | B16: 7 | C16: 7 | D16: 7/9 | E16: PASS | F16: Wording differs but boundaries correspond for MD-001/002/003/006/007/008/009.
A17: Split/merge items | B17: 2 | C17: 2 | D17: MD-004, MD-005 | E17: RECONCILE | F17: Causal claims were split by Coder01 and retained as relations by Coder02.
A18: Identity fields | B18: Coded ID | C18: Coded ID | D18: Private key required | E18: CHECK | F18: Full name/signature cells contain coder IDs; retain a private identity key or obtain named signatures.

Sheet Materials
A1: Blind Materials — unchanged from Phase 1
A4: Use only these displayed texts when confirming the common proposition inventory. Identity keys remain withheld.
A6: Blind item ID | B6: Topic | C6: Generated draft | D6: Participant source
A7: MD-001 | B7: Experience | C7: Typed response extract: “It happened on a train.” “The train was packed and it stopped suddenly with a loud screeching noise. I could not move away from the crowd, and I felt trapped and overwhelmed.” | D7: SRC-01: It happened on a train. SRC-02: The train was packed and it stopped suddenly with a loud screeching noise. I could not move away from the crowd, and I felt trapped and overwhelmed.
A8: MD-002 | B8: Experience | C8: Typed response extract: “It happened on a train.” “I do not remember anything else about it.” | D8: SRC-01: It happened on a train. SRC-02: I do not remember anything else about it.
A9: MD-003 | B9: Experience | C9: Typed response extract: “A recent example was a crowded train that stopped between stations while alarms sounded. The noise and lack of space made me feel trapped and overwhelmed.” | D9: SRC-01: A recent example was a crowded train that stopped between stations while alarms sounded. The noise and lack of space made me feel trapped and overwhelmed.
A10: MD-004 | B10: Support concept reaction | C10: Typed response extract: “The squeeze interaction seems useful because it would give my hands a focus, and gentle haptics might help me pace my breathing. I would avoid scent because it can be another trigger, and I would want every feature to be optional.” | D10: SRC-01: The squeeze interaction seems useful because it would give my hands a focus, and gentle haptics might help me pace my breathing. I would avoid scent because it can be another trigger, and I would want every feature to be optional.
A11: MD-005 | B11: Coping & support | C11: Typed response extract: “I covered my ears, focused on slow breathing, and left at the next stop. A quieter carriage or a warning before the alarm would have helped. The repeated announcements did not help because they added more noise.” | D11: SRC-01: I covered my ears, focused on slow breathing, and left at the next stop. A quieter carriage or a warning before the alarm would have helped. The repeated announcements did not help because they added more noise.
A12: MD-006 | B12: Experience | C12: Typed response extract: “On a crowded train, the carriage stopped between stations while alarms sounded. The noise and crowding made me feel trapped and overwhelmed.” | D12: SRC-01: On a crowded train, the carriage stopped between stations while alarms sounded. The noise and crowding made me feel trapped and overwhelmed.
A13: MD-007 | B13: Triggers & signs | C13: Typed response extract: “The sharp braking noise, flashing carriage lights, and crowding were the strongest triggers. My shoulders tightened, my heart raced, and I felt panicked.” | D13: SRC-01: The sharp braking noise, flashing carriage lights, and crowding were the strongest triggers. My shoulders tightened, my heart raced, and I felt panicked.
A14: MD-008 | B14: Experience | C14: Typed response extract: “Last month on a crowded train, the carriage stopped between stations while alarms and announcements were sounding. People were pressed close to me, and the combined noise and crowding made me feel trapped and overwhelmed.” | D14: SRC-01: Last month on a crowded train, the carriage stopped between stations while alarms and announcements were sounding. People were pressed close to me, and the combined noise and crowding made me feel trapped and overwhelmed.
A15: MD-009 | B15: Public-use acceptability | C15: Typed response extract: “I might use it while commuting if it looked discreet and made no sound. I would be embarrassed by obvious lights, and scent would be a concern for people nearby in a shared space.” | D15: SRC-01: I might use it while commuting if it looked discreet and made no sound. I would be embarrassed by obvious lights, and scent would be a concern for people nearby in a shared space.

Sheet Boundary Review
A1: Boundary Review — two split/merge decisions
A4: Only proposition boundaries are reconciled here. Support labels remain prohibited until Phase 2.
A6: Blind item | B6: Generated draft | C6: Coder01 independent inventory | D6: Coder02 independent inventory | E6: Provisional common inventory | F6: Method note
A7: MD-004 | B7: Typed response extract: “The squeeze interaction seems useful because it would give my hands a focus, and gentle haptics might help me pace my breathing. I would avoid scent because it can be another trigger, and I would want every feature to be optional.” | C7: 1. The squeeze interaction seemed useful. 2. The squeeze interaction would give the participant's hands a focus. 3. Gentle haptics might help the participant pace their breathing. 4. The participant would avoid scent. 5. Scent could be another trigger for the participant. 6. The participant wanted every feature to be optional. | D7: 1. The squeeze interaction was seen as useful because it would give the participant's hands something to focus on. 2. Gentle haptics might help with pacing the participant's breathing. 3. The participant would avoid scent because it could act as another trigger. 4. The participant wanted all features to remain optional. | E7: 1. The squeeze interaction seemed useful because it would give the participant's hands a focus. 2. Gentle haptics might help the participant pace their breathing. 3. The participant would avoid scent because it could be another trigger. 4. The participant wanted every feature to be optional. | F7: Provisional choice retains each explicit causal relation as one independently checkable relational proposition. Both coders must confirm or edit it jointly.
A8: MD-005 | B8: Typed response extract: “I covered my ears, focused on slow breathing, and left at the next stop. A quieter carriage or a warning before the alarm would have helped. The repeated announcements did not help because they added more noise.” | C8: 1. The participant covered their ears. 2. The participant focused on slow breathing. 3. The participant left at the next stop. 4. A quieter carriage would have helped the participant. 5. A warning before the alarm would have helped the participant. 6. The repeated announcements did not help. 7. The repeated announcements added more noise. | D8: 1. The participant covered their ears. 2. The participant used slow breathing. 3. The participant got off at the next stop. 4. A quieter carriage would have been helpful. 5. Advance warning before the alarm would have been helpful. 6. The repeated announcements were unhelpful because they added further noise. | E8: 1. The participant covered their ears. 2. The participant focused on slow breathing. 3. The participant left at the next stop. 4. A quieter carriage would have helped the participant. 5. A warning before the alarm would have helped the participant. 6. The repeated announcements did not help because they added more noise. | F8: Provisional choice retains each explicit causal relation as one independently checkable relational proposition. Both coders must confirm or edit it jointly.

Sheet Final Inventory
A1: Agreed Final Proposition Inventory
A4: Yellow proposition cells contain a provisional 46-proposition inventory. Both coders must jointly edit or accept it. Keep indices consecutive within each item and leave unused reserve rows blank.
A6: Blind item ID | B6: Proposition index | C6: Agreed atomic proposition | D6: Slot QA | E6: Proposal basis
A7: MD-001 | B7: 1 | C7: The experience happened on a train. | D7: =IF(C7="","UNUSED",IF(COUNTBLANK(C$7:C7)=0,"USED","GAP")) -> USED | E7: Equivalent independent boundaries; wording standardized
A8: MD-001 | B8: 2 | C8: The train was packed. | D8: =IF(C8="","UNUSED",IF(COUNTBLANK(C$7:C8)=0,"USED","GAP")) -> USED | E8: Equivalent independent boundaries; wording standardized
A9: MD-001 | B9: 3 | C9: The train stopped suddenly. | D9: =IF(C9="","UNUSED",IF(COUNTBLANK(C$7:C9)=0,"USED","GAP")) -> USED | E9: Equivalent independent boundaries; wording standardized
A10: MD-001 | B10: 4 | C10: A loud screeching noise accompanied the stop. | D10: =IF(C10="","UNUSED",IF(COUNTBLANK(C$7:C10)=0,"USED","GAP")) -> USED | E10: Equivalent independent boundaries; wording standardized
A11: MD-001 | B11: 5 | C11: The participant could not move away from the crowd. | D11: =IF(C11="","UNUSED",IF(COUNTBLANK(C$7:C11)=0,"USED","GAP")) -> USED | E11: Equivalent independent boundaries; wording standardized
A12: MD-001 | B12: 6 | C12: The participant felt trapped. | D12: =IF(C12="","UNUSED",IF(COUNTBLANK(C$7:C12)=0,"USED","GAP")) -> USED | E12: Equivalent independent boundaries; wording standardized
A13: MD-001 | B13: 7 | C13: The participant felt overwhelmed. | D13: =IF(C13="","UNUSED",IF(COUNTBLANK(C$7:C13)=0,"USED","GAP")) -> USED | E13: Equivalent independent boundaries; wording standardized
A14: MD-001 | B14: 8 | D14: =IF(C14="","UNUSED",IF(COUNTBLANK(C$7:C14)=0,"USED","GAP")) -> UNUSED
A15: MD-001 | B15: 9 | D15: =IF(C15="","UNUSED",IF(COUNTBLANK(C$7:C15)=0,"USED","GAP")) -> UNUSED
A16: MD-001 | B16: 10 | D16: =IF(C16="","UNUSED",IF(COUNTBLANK(C$7:C16)=0,"USED","GAP")) -> UNUSED
A17: MD-001 | B17: 11 | D17: =IF(C17="","UNUSED",IF(COUNTBLANK(C$7:C17)=0,"USED","GAP")) -> UNUSED
A18: MD-001 | B18: 12 | D18: =IF(C18="","UNUSED",IF(COUNTBLANK(C$7:C18)=0,"USED","GAP")) -> UNUSED
A19: MD-002 | B19: 1 | C19: The experience happened on a train. | D19: =IF(C19="","UNUSED",IF(COUNTBLANK(C$19:C19)=0,"USED","GAP")) -> USED | E19: Equivalent independent boundaries; wording standardized
A20: MD-002 | B20: 2 | C20: The participant did not remember anything else about it. | D20: =IF(C20="","UNUSED",IF(COUNTBLANK(C$19:C20)=0,"USED","GAP")) -> USED | E20: Equivalent independent boundaries; wording standardized
A21: MD-002 | B21: 3 | D21: =IF(C21="","UNUSED",IF(COUNTBLANK(C$19:C21)=0,"USED","GAP")) -> UNUSED
A22: MD-002 | B22: 4 | D22: =IF(C22="","UNUSED",IF(COUNTBLANK(C$19:C22)=0,"USED","GAP")) -> UNUSED
A23: MD-002 | B23: 5 | D23: =IF(C23="","UNUSED",IF(COUNTBLANK(C$19:C23)=0,"USED","GAP")) -> UNUSED
A24: MD-002 | B24: 6 | D24: =IF(C24="","UNUSED",IF(COUNTBLANK(C$19:C24)=0,"USED","GAP")) -> UNUSED
A25: MD-002 | B25: 7 | D25: =IF(C25="","UNUSED",IF(COUNTBLANK(C$19:C25)=0,"USED","GAP")) -> UNUSED
A26: MD-002 | B26: 8 | D26: =IF(C26="","UNUSED",IF(COUNTBLANK(C$19:C26)=0,"USED","GAP")) -> UNUSED
A27: MD-002 | B27: 9 | D27: =IF(C27="","UNUSED",IF(COUNTBLANK(C$19:C27)=0,"USED","GAP")) -> UNUSED
A28: MD-002 | B28: 10 | D28: =IF(C28="","UNUSED",IF(COUNTBLANK(C$19:C28)=0,"USED","GAP")) -> UNUSED
A29: MD-002 | B29: 11 | D29: =IF(C29="","UNUSED",IF(COUNTBLANK(C$19:C29)=0,"USED","GAP")) -> UNUSED
A30: MD-002 | B30: 12 | D30: =IF(C30="","UNUSED",IF(COUNTBLANK(C$19:C30)=0,"USED","GAP")) -> UNUSED
A31: MD-003 | B31: 1 | C31: The example occurred on a crowded train. | D31: =IF(C31="","UNUSED",IF(COUNTBLANK(C$31:C31)=0,"USED","GAP")) -> USED | E31: Equivalent independent boundaries; wording standardized
A32: MD-003 | B32: 2 | C32: The train stopped between stations. | D32: =IF(C32="","UNUSED",IF(COUNTBLANK(C$31:C32)=0,"USED","GAP")) -> USED | E32: Equivalent independent boundaries; wording standardized
A33: MD-003 | B33: 3 | C33: Alarms sounded during the event. | D33: =IF(C33="","UNUSED",IF(COUNTBLANK(C$31:C33)=0,"USED","GAP")) -> USED | E33: Equivalent independent boundaries; wording standardized
A34: MD-003 | B34: 4 | C34: Noise and lack of space made the participant feel trapped. | D34: =IF(C34="","UNUSED",IF(COUNTBLANK(C$31:C34)=0,"USED","GAP")) -> USED | E34: Equivalent independent boundaries; wording standardized
A35: MD-003 | B35: 5 | C35: Noise and lack of space made the participant feel overwhelmed. | D35: =IF(C35="","UNUSED",IF(COUNTBLANK(C$31:C35)=0,"USED","GAP")) -> USED | E35: Equivalent independent boundaries; wording standardized
A36: MD-003 | B36: 6 | D36: =IF(C36="","UNUSED",IF(COUNTBLANK(C$31:C36)=0,"USED","GAP")) -> UNUSED
A37: MD-003 | B37: 7 | D37: =IF(C37="","UNUSED",IF(COUNTBLANK(C$31:C37)=0,"USED","GAP")) -> UNUSED
A38: MD-003 | B38: 8 | D38: =IF(C38="","UNUSED",IF(COUNTBLANK(C$31:C38)=0,"USED","GAP")) -> UNUSED
A39: MD-003 | B39: 9 | D39: =IF(C39="","UNUSED",IF(COUNTBLANK(C$31:C39)=0,"USED","GAP")) -> UNUSED
A40: MD-003 | B40: 10 | D40: =IF(C40="","UNUSED",IF(COUNTBLANK(C$31:C40)=0,"USED","GAP")) -> UNUSED
A41: MD-003 | B41: 11 | D41: =IF(C41="","UNUSED",IF(COUNTBLANK(C$31:C41)=0,"USED","GAP")) -> UNUSED
A42: MD-003 | B42: 12 | D42: =IF(C42="","UNUSED",IF(COUNTBLANK(C$31:C42)=0,"USED","GAP")) -> UNUSED
A43: MD-004 | B43: 1 | C43: The squeeze interaction seemed useful because it would give the participant's hands a focus. | D43: =IF(C43="","UNUSED",IF(COUNTBLANK(C$43:C43)=0,"USED","GAP")) -> USED | E43: Causal-relation reconciliation
...

Sheet Item Confirmation
A1: Item-level Joint Confirmation
A4: After reviewing and, if necessary, editing Final Inventory, both coders confirm each item. Add a joint note for any change from the provisional inventory.
A6: Blind item | B6: Coder01 Phase 1 count | C6: Coder02 Phase 1 count | D6: Provisional count | E6: Boundary status | F6: Coder01 confirms? | G6: Coder02 confirms? | H6: Joint note | I6: Item QA
A7: MD-001 | B7: 7 | C7: 7 | D7: 7 | E7: Equivalent boundaries | F7: Yes | G7: Yes | H7: Accepted. Independent boundaries were equivalent; common wording retained. | I7: =IF(AND(F7="Yes",G7="Yes",COUNTIFS('Final Inventory'!$A$7:$A$18,A7,'Final Inventory'!$D$7:$D$18,"USED")>0,COUNTIF('Final Inventory'!$D$7:$D$18,"GAP")=0),"PASS","PENDING") -> PASS
A8: MD-002 | B8: 2 | C8: 2 | D8: 2 | E8: Equivalent boundaries | F8: Yes | G8: Yes | H8: Accepted. Independent boundaries were equivalent; common wording retained. | I8: =IF(AND(F8="Yes",G8="Yes",COUNTIFS('Final Inventory'!$A$19:$A$30,A8,'Final Inventory'!$D$19:$D$30,"USED")>0,COUNTIF('Final Inventory'!$D$19:$D$30,"GAP")=0),"PASS","PENDING") -> PASS
A9: MD-003 | B9: 5 | C9: 5 | D9: 5 | E9: Equivalent boundaries | F9: Yes | G9: Yes | H9: Accepted. Independent boundaries were equivalent; common wording retained. | I9: =IF(AND(F9="Yes",G9="Yes",COUNTIFS('Final Inventory'!$A$31:$A$42,A9,'Final Inventory'!$D$31:$D$42,"USED")>0,COUNTIF('Final Inventory'!$D$31:$D$42,"GAP")=0),"PASS","PENDING") -> PASS
A10: MD-004 | B10: 6 | C10: 4 | D10: 4 | E10: Split/merge reconciliation | F10: Yes | G10: Yes | H10: Agreed to retain each explicit 'because' relation as one atomic relational proposition rather than splitting the evaluative claim from its stated reason. | I10: =IF(AND(F10="Yes",G10="Yes",COUNTIFS('Final Inventory'!$A$43:$A$54,A10,'Final Inventory'!$D$43:$D$54,"USED")>0,COUNTIF('Final Inventory'!$D$43:$D$54,"GAP")=0),"PASS","PENDING") -> PASS
A11: MD-005 | B11: 7 | C11: 6 | D11: 6 | E11: Split/merge reconciliation | F11: Yes | G11: Yes | H11: Agreed to retain 'did not help because they added more noise' as one atomic relational proposition so the stated causal relation is preserved. | I11: =IF(AND(F11="Yes",G11="Yes",COUNTIFS('Final Inventory'!$A$55:$A$66,A11,'Final Inventory'!$D$55:$D$66,"USED")>0,COUNTIF('Final Inventory'!$D$55:$D$66,"GAP")=0),"PASS","PENDING") -> PASS
A12: MD-006 | B12: 5 | C12: 5 | D12: 5 | E12: Equivalent boundaries | F12: Yes | G12: Yes | H12: Accepted. Independent boundaries were equivalent; common wording retained. | I12: =IF(AND(F12="Yes",G12="Yes",COUNTIFS('Final Inventory'!$A$67:$A$78,A12,'Final Inventory'!$D$67:$D$78,"USED")>0,COUNTIF('Final Inventory'!$D$67:$D$78,"GAP")=0),"PASS","PENDING") -> PASS
A13: MD-007 | B13: 6 | C13: 6 | D13: 6 | E13: Equivalent boundaries | F13: Yes | G13: Yes | H13: Accepted. Independent boundaries were equivalent; common wording retained. | I13: =IF(AND(F13="Yes",G13="Yes",COUNTIFS('Final Inventory'!$A$79:$A$90,A13,'Final Inventory'!$D$79:$D$90,"USED")>0,COUNTIF('Final Inventory'!$D$79:$D$90,"GAP")=0),"PASS","PENDING") -> PASS
A14: MD-008 | B14: 8 | C14: 8 | D14: 8 | E14: Equivalent boundaries | F14: Yes | G14: Yes | H14: Accepted. Independent boundaries were equivalent; common wording retained. | I14: =IF(AND(F14="Yes",G14="Yes",COUNTIFS('Final Inventory'!$A$91:$A$102,A14,'Final Inventory'!$D$91:$D$102,"USED")>0,COUNTIF('Final Inventory'!$D$91:$D$102,"GAP")=0),"PASS","PENDING") -> PASS
A15: MD-009 | B15: 3 | C15: 3 | D15: 3 | E15: Equivalent boundaries | F15: Yes | G15: Yes | H15: Accepted. Independent boundaries were equivalent; common wording retained. | I15: =IF(AND(F15="Yes",G15="Yes",COUNTIFS('Final Inventory'!$A$103:$A$114,A15,'Final Inventory'!$D$103:$D$114,"USED")>0,COUNTIF('Final Inventory'!$D$103:$D$114,"GAP")=0),"PASS","PENDING") -> PASS

Sheet Joint Sign-off
A1: Joint Reconciliation Sign-off
A4: Complete only after the final inventory and all nine item confirmations are agreed. This is a consensus stage; it does not replace the frozen independent returns.
A6: Reconciliation method | B6: Joint review of the two frozen independent inventories; split/merge differences resolved by retaining the smallest independently checkable proposition while preserving explicit causal relations.
A7: Coder01 full name / signature | B7: Coder01
A8: Coder02 full name / signature | B8: Coder02
A9: Reconciliation started at (ISO 8601 with timezone) | B9: 46244.688
A10: Reconciliation completed at (ISO 8601 with timezone) | B10: 46244.696
A11: Independent Phase 1 originals remain unchanged? | B11: Yes
A12: Condition/item identity key remained concealed? | B12: Yes
A13: Final inventory preserves stated relations and has no gaps? | B13: Yes
A14: Coder01 confirms the final inventory for Phase 2? | B14: Yes
A15: Coder02 confirms the final inventory for Phase 2? | B15: Yes
A16: Joint resolution note | B16: Both coders accepted the 46-proposition common inventory. MD-004 and MD-005 were reconciled by retaining the explicit causal 'because' relation within one proposition; all other items retained equivalent boundaries with standardized wording.
A17: Sign-off QA | B17: =IF(AND(B6<>"",B7<>"",B8<>"",B9<>"",B10<>"",B11="Yes",B12="Yes",B13="Yes",B14="Yes",B15="Yes",COUNTIF('Item Confirmation'!$I$7:$I$15,"PASS")=9),"PASS","PENDING") -> PASS
A19: Important | B19: If coded IDs are used above, retain a private identity key linking each ID to the real person. Do not place the key in a public evidence package.

Sheet QA Summary
A1: Reconciliation QA Summary
A4: Phase 2 may be issued only when Overall reconciliation QA = PASS. External validation of returned files remains authoritative.
A6: Check | B6: Expected | C6: Observed | D6: Status | E6: Interpretation
A7: Final inventory used propositions | B7: >=1 per item | C7: =COUNTIF('Final Inventory'!$D$7:$D$114,"USED") -> 46 | D7: =IF(AND(C7>=9,C8=0),"PASS","PENDING") -> PASS | E7: The exact total may change during reconciliation, but every item must retain at least one proposition.
A8: Final inventory gap rows | B8: 0 | C8: =COUNTIF('Final Inventory'!$D$7:$D$114,"GAP") -> 0 | D8: =IF(C8=0,"PASS","PENDING") -> PASS | E8: No used proposition may follow a blank slot within an item.
A9: Items jointly confirmed | B9: 9 | C9: =COUNTIF('Item Confirmation'!$I$7:$I$15,"PASS") -> 9 | D9: =IF(C9=9,"PASS","PENDING") -> PASS | E9: Both coders must confirm all nine final item inventories.
A10: Coder sign-off | B10: PASS | C10: =IF(AND('Joint Sign-off'!$B$7<>"",'Joint Sign-off'!$B$8<>"",'Joint Sign-off'!$B$14="Yes",'Joint Sign-off'!$B$15="Yes"),"PASS","PENDING") -> PASS | D10: =C10 -> PASS | E10: Both coders must provide signatures and final confirmation.
A11: Blindness/original-integrity declarations | B11: PASS | C11: =IF(AND('Joint Sign-off'!$B$11="Yes",'Joint Sign-off'!$B$12="Yes",'Joint Sign-off'!$B$13="Yes"),"PASS","PENDING") -> PASS | D11: =C11 -> PASS | E11: Original returns remain frozen and identity keys remain concealed.
A12: Overall reconciliation QA | B12: PASS | C12: ='Joint Sign-off'!$B$17 -> PASS | D12: =C12 -> PASS | E12: Issue Phase 2 only after this row shows PASS.
